<?xml version="1.0" ?>
<!-- =================================================================================== -->
<!-- |    This document was autogenerated by xacro from scara_e1_model_3joints.urdf.xacro | -->
<!-- |    EDITING THIS FILE BY HAND IS NOT RECOMMENDED                                 | -->
<!-- =================================================================================== -->
<robot name="scara_e1_3joints" xmlns:xacro="http://ros.org/wiki/xacro">
  <link name="world">
    <visual>
      <geometry>
        <box size="1.5 0.8 0.001"/>
      </geometry>
      <origin rpy="0 0 0" xyz="0 0 0"/>
      <material name="Gazebo/Black">
       </material>
    </visual>
  </link>
  <gazebo reference="world">
    <selfCollide>False</selfCollide>
  </gazebo>

  <link name="base_link">
    <inertial>
      <origin rpy="0 0 0" xyz="8.625E-08 -4.6583E-06 0.03145"/>
      <mass value="0.22652"/>
      <inertia ixx="0.00020005" ixy="-4.2442E-10" ixz="-2.9069E-10" iyy="0.00017832" iyz="-3.4402E-08" izz="0.00013478"/>
    </inertial>
    <visual>
      <origin rpy="0 0 0" xyz="0 0 0"/>
      <geometry>
        <mesh filename="package://articulated_arm_description/meshes/AR_Base_metal.stl" scale="0.001 0.001 0.001"/>
      </geometry>
      <material name="Gazebo/Grey">
        <color rgba="0. 0. 0. 1"/>
      </material>
    </visual>
  </link>
  <gazebo reference="base_link">
    <material>Gazebo/Grey</material>
    <selfCollide>False</selfCollide>
  </gazebo>

  <link name="scara_e1_base_screws">
    <inertial>
      <origin rpy="0 0 0" xyz="8.625E-08 -4.6583E-06 0.03145"/>
      <mass value="0.22652"/>
      <inertia ixx="0.00020005" ixy="-4.2442E-10" ixz="-2.9069E-10" iyy="0.00017832" iyz="-3.4402E-08" izz="0.00013478"/>
    </inertial>
    <visual>
      <origin rpy="0 0 0" xyz="0 0 0"/>
      <geometry>
        <mesh filename="package://articulated_arm_description/meshes/AR_Base_black.stl" scale="0.001 0.001 0.001"/>
      </geometry>
      <material name="Gazebo/Black">
        <color rgba="0. 0. 0. 1"/>
      </material>
    </visual>
  </link>
  <gazebo reference="scara_e1_base_screws">
    <material>Gazebo/Black</material>
    <selfCollide>False</selfCollide>
  </gazebo>

  <link name="articulated_arm_hans_elbow">
    <inertial>
      <origin rpy="0 0 0" xyz="8.625E-08 -4.6583E-06 0.03145"/>
      <mass value="0.22652"/>
      <inertia ixx="0.00020005" ixy="-4.2442E-10" ixz="-2.9069E-10" iyy="0.00017832" iyz="-3.4402E-08" izz="0.00013478"/>
    </inertial>
    <visual>
      <origin rpy="0 0 0" xyz="0 0 0"/>
      <geometry>
        <mesh filename="package://articulated_arm_description/meshes/hans/AR_Hans_black.stl" scale="0.001 0.001 0.001"/>
      </geometry>
      <material name="Gazebo/Blue">
        <color rgba="0. 0. 0. 1"/>
      </material>
    </visual>
  </link>
  <gazebo reference="articulated_arm_hans_elbow">
    <material>Gazebo/Blue</material>
    <selfCollide>False</selfCollide>
  </gazebo>

  <link name="articulated_arm_hans">
    <inertial>
      <origin rpy="0 0 0" xyz="8.625E-08 -4.6583E-06 0.03145"/>
      <mass value="0.22652"/>
      <inertia ixx="0.00020005" ixy="-4.2442E-10" ixz="-2.9069E-10" iyy="0.00017832" iyz="-3.4402E-08" izz="0.00013478"/>
    </inertial>
    <visual>
      <origin rpy="0 0 0" xyz="0 0 0"/>
      <geometry>
        <mesh filename="package://articulated_arm_description/meshes/hans/AR_Hans_white.stl" scale="0.001 0.001 0.001"/>
      </geometry>
      <material name="Gazebo/Black">
        <color rgba="0. 0. 0. 1"/>
      </material>
    </visual>
    <collision>
      <origin rpy="0 0 0" xyz="0 0 0"/>
      <geometry>
        <mesh filename="package://articulated_arm_description/meshes/simplified/HANS_simpli.stl" scale="0.001 0.001 0.001"/>
      </geometry>
    </collision>
  </link>
  <gazebo reference="articulated_arm_hans">
    <material>Gazebo/Black</material>
    <selfCollide>True</selfCollide>
  </gazebo>

  <link name="arm_link">
    <inertial>
      <origin rpy="0 0 0" xyz="8.625E-08 -4.6583E-06 0.03145"/>
      <mass value="0.22652"/>
      <inertia ixx="0.00020005" ixy="-4.2442E-10" ixz="-2.9069E-10" iyy="0.00017832" iyz="-3.4402E-08" izz="0.00013478"/>
    </inertial>
    <visual>
      <origin rpy="0 0 0" xyz="0 0 0"/>
      <geometry>
        <mesh filename="package://articulated_arm_description/meshes/AR_Link1_HANs_adapter.stl" scale="0.001 0.001 0.001"/>
      </geometry>
      <material name="Gazebo/Black">
        <color rgba="0. 0. 0. 1"/>
      </material>
    </visual>
  </link>
  <gazebo reference="arm_link">
    <material>Gazebo/Black</material>
    <selfCollide>False</selfCollide>
  </gazebo>

  <link name="arm_link_arm">
    <inertial>
      <origin rpy="0 0 0" xyz="8.625E-08 -4.6583E-06 0.03145"/>
      <mass value="0.22652"/>
      <inertia ixx="0.00020005" ixy="-4.2442E-10" ixz="-2.9069E-10" iyy="0.00017832" iyz="-3.4402E-08" izz="0.00013478"/>
    </inertial>
    <visual>
      <origin rpy="0 0 0" xyz="0 0 0"/>
      <geometry>
        <mesh filename="package://articulated_arm_description/meshes/AR_Link1_black.stl" scale="0.001 0.001 0.001"/>
      </geometry>
      <material name="Gazebo/Black">
        <color rgba="0. 0. 0. 1"/>
      </material>
    </visual>
    <collision>
      <origin rpy="0 0 0" xyz="0 0 0"/>
      <geometry>
        <mesh filename="package://articulated_arm_description/meshes/simplified/LINK_simpli.stl" scale="0.001 0.001 0.001"/>
      </geometry>
    </collision>
  </link>
  <gazebo reference="arm_link_arm">
    <material>Gazebo/Black</material>
    <selfCollide>True</selfCollide>
  </gazebo>

  <link name="arm_link_paladapter">
    <inertial>
      <origin rpy="0 0 0" xyz="8.625E-08 -4.6583E-06 0.03145"/>
      <mass value="0.22652"/>
      <inertia ixx="0.00020005" ixy="-4.2442E-10" ixz="-2.9069E-10" iyy="0.00017832" iyz="-3.4402E-08" izz="0.00013478"/>
    </inertial>
    <visual>
      <origin rpy="0 0 0" xyz="0 0 0"/>
      <geometry>
        <mesh filename="package://articulated_arm_description/meshes/AR_Link1_PALadapter.stl" scale="0.001 0.001 0.001"/>
      </geometry>
      <material name="Gazebo/Grey">
        <color rgba="0. 0. 0. 1"/>
      </material>
    </visual>
  </link>
  <gazebo reference="arm_link_paladapter">
    <material>Gazebo/Grey</material>
    <selfCollide>False</selfCollide>
  </gazebo>

  <link name="pal_motor">
    <inertial>
      <origin rpy="0 0 0" xyz="8.625E-08 -4.6583E-06 0.03145"/>
      <mass value="0.22652"/>
      <inertia ixx="0.00020005" ixy="-4.2442E-10" ixz="-2.9069E-10" iyy="0.00017832" iyz="-3.4402E-08" izz="0.00013478"/>
    </inertial>
    <visual>
      <origin rpy="0 0 0" xyz="0 0 0"/>
      <geometry>
        <mesh filename="package://articulated_arm_description/meshes/AR_PAL_metal.stl" scale="0.001 0.001 0.001"/>
      </geometry>
      <material name="Gazebo/Grey">
        <color rgba="0. 0. 0. 1"/>
      </material>
    </visual>
    <collision>
      <origin rpy="0 0 0" xyz="0 0 0"/>
      <geometry>
        <mesh filename="package://articulated_arm_description/meshes/simplified/PAL_simpli.stl" scale="0.001 0.001 0.001"/>
      </geometry>
    </collision>
  </link>
  <gazebo reference="pal_motor">
    <material>Gazebo/Grey</material>
    <selfCollide>True</selfCollide>
  </gazebo>

  <link name="pal_motor2">
    <inertial>
      <origin rpy="0 0 0" xyz="8.625E-08 -4.6583E-06 0.03145"/>
      <mass value="0.22652"/>
      <inertia ixx="0.00020005" ixy="-4.2442E-10" ixz="-2.9069E-10" iyy="0.00017832" iyz="-3.4402E-08" izz="0.00013478"/>
    </inertial>
    <visual>
      <origin rpy="0 0 0" xyz="0 0 0"/>
      <geometry>
        <mesh filename="package://articulated_arm_description/meshes/AR_PAL_black.stl" scale="0.001 0.001 0.001"/>
      </geometry>
      <material name="Gazebo/Black">
        <color rgba="0. 0. 0. 1"/>
      </material>
    </visual>
  </link>
  <gazebo reference="pal_motor2">
    <material>Gazebo/Black</material>
    <selfCollide>False</selfCollide>
  </gazebo>

  <link name="pal_motor_adapter">
    <inertial>
      <origin rpy="0 0 0" xyz="8.625E-08 -4.6583E-06 0.03145"/>
      <mass value="0.22652"/>
      <inertia ixx="0.00020005" ixy="-4.2442E-10" ixz="-2.9069E-10" iyy="0.00017832" iyz="-3.4402E-08" izz="0.00013478"/>
    </inertial>
    <visual>
      <origin rpy="0 0 0" xyz="0 0 0"/>
      <geometry>
        <mesh filename="package://articulated_arm_description/meshes/AR_PALadapter_front.stl" scale="0.001 0.001 0.001"/>
      </geometry>
      <material name="Gazebo/Grey">
        <color rgba="0. 0. 0. 1"/>
      </material>
    </visual>
  </link>
  <gazebo reference="pal_motor_adapter">
    <material>Gazebo/Grey</material>
    <selfCollide>False</selfCollide>
  </gazebo>

  <link name="pal_link_adapter">
    <inertial>
      <origin rpy="0 0 0" xyz="8.625E-08 -4.6583E-06 0.03145"/>
      <mass value="0.22652"/>
      <inertia ixx="0.00020005" ixy="-4.2442E-10" ixz="-2.9069E-10" iyy="0.00017832" iyz="-3.4402E-08" izz="0.00013478"/>
    </inertial>
    <visual>
      <origin rpy="0 0 0" xyz="0 0 0"/>
      <geometry>
        <mesh filename="package://articulated_arm_description/meshes/pal-to-hebi/AR_Link2_black.stl" scale="0.001 0.001 0.001"/>
      </geometry>
      <material name="Gazebo/Black">
        <color rgba="0. 0. 0. 1"/>
      </material>
    </visual>
    <collision>
      <origin rpy="0 0 0" xyz="0 0 0"/>
      <geometry>
        <mesh filename="package://articulated_arm_description/meshes/simplified/LINK2_simpli.stl" scale="0.001 0.001 0.001"/>
      </geometry>
    </collision>
  </link>
  <gazebo reference="pal_link_adapter">
    <material>Gazebo/Black</material>
    <selfCollide>False</selfCollide>
  </gazebo>

  <link name="adapter_hebi">
    <inertial>
      <origin rpy="0 0 0" xyz="8.625E-08 -4.6583E-06 0.03145"/>
      <mass value="0.22652"/>
      <inertia ixx="0.00020005" ixy="-4.2442E-10" ixz="-2.9069E-10" iyy="0.00017832" iyz="-3.4402E-08" izz="0.00013478"/>
    </inertial>
    <visual>
      <origin rpy="0 0 0" xyz="0 0 0"/>
      <geometry>
        <mesh filename="package://articulated_arm_description/meshes/pal-to-hebi/AR_Link2_HEBIadapter.stl" scale="0.001 0.001 0.001"/>
      </geometry>
      <material name="Gazebo/Grey">
        <color rgba="0. 0. 0. 1"/>
      </material>
    </visual>
  </link>
  <gazebo reference="adapter_hebi">
    <material>Gazebo/Grey</material>
    <selfCollide>False</selfCollide>
  </gazebo>

  <link name="hebi_black">
    <inertial>
      <origin rpy="0 0 0" xyz="8.625E-08 -4.6583E-06 0.03145"/>
      <mass value="0.22652"/>
      <inertia ixx="0.00020005" ixy="-4.2442E-10" ixz="-2.9069E-10" iyy="0.00017832" iyz="-3.4402E-08" izz="0.00013478"/>
    </inertial>
    <visual>
      <origin rpy="0 0 0" xyz="0 0 0"/>
      <geometry>
        <mesh filename="package://articulated_arm_description/meshes/hebi/AR_HEBI_black.stl" scale="0.001 0.001 0.001"/>
      </geometry>
      <material name="Gazebo/Black">
        <color rgba="0. 0. 0. 1"/>
      </material>
    </visual>
    <collision>
      <origin rpy="0 0 0" xyz="0 0 0"/>
      <geometry>
        <mesh filename="package://articulated_arm_description/meshes/simplified/HEBI_simpli.stl" scale="0.001 0.001 0.001"/>
      </geometry>
    </collision>
  </link>
  <gazebo reference="hebi_black">
    <material>Gazebo/Black</material>
    <selfCollide>False</selfCollide>
  </gazebo>

  <link name="hebi_red">
    <inertial>
      <origin rpy="0 0 0" xyz="8.625E-08 -4.6583E-06 0.03145"/>
      <mass value="0.22652"/>
      <inertia ixx="0.00020005" ixy="-4.2442E-10" ixz="-2.9069E-10" iyy="0.00017832" iyz="-3.4402E-08" izz="0.00013478"/>
    </inertial>
    <visual>
      <origin rpy="0 0 0" xyz="0 0 0"/>
      <geometry>
        <mesh filename="package://articulated_arm_description/meshes/hebi/AR_HEBI_red.stl" scale="0.001 0.001 0.001"/>
      </geometry>
      <material name="Gazebo/Red">
        <color rgba="0. 0. 0. 1"/>
      </material>
    </visual>
  </link>
  <gazebo reference="hebi_red">
    <material>Gazebo/Red</material>
    <selfCollide>False</selfCollide>
  </gazebo>

  <link name="hebi_adapter">
    <inertial>
      <origin rpy="0 0 0" xyz="8.625E-08 -4.6583E-06 0.03145"/>
      <mass value="0.22652"/>
      <inertia ixx="0.00020005" ixy="-4.2442E-10" ixz="-2.9069E-10" iyy="0.00017832" iyz="-3.4402E-08" izz="0.00013478"/>
    </inertial>
    <visual>
      <origin rpy="0 0 0" xyz="0 0 0"/>
      <geometry>
        <mesh filename="package://articulated_arm_description/meshes/hebi/AR_HEBIadapter_front.stl" scale="0.001 0.001 0.001"/>
      </geometry>
      <material name="Gazebo/Grey">
        <color rgba="0. 0. 0. 1"/>
      </material>
    </visual>
  </link>
  <gazebo reference="hebi_adapter">
    <material>Gazebo/Grey</material>
    <selfCollide>False</selfCollide>
  </gazebo>

  <link name="end_effector_adapter">
    <inertial>
      <origin rpy="0 0 0" xyz="8.625E-08 -4.6583E-06 0.03145"/>
      <mass value="0.22652"/>
      <inertia ixx="0.00020005" ixy="-4.2442E-10" ixz="-2.9069E-10" iyy="0.00017832" iyz="-3.4402E-08" izz="0.00013478"/>
    </inertial>
    <visual>
      <origin rpy="0 0 0" xyz="0 0 0"/>
      <geometry>
        <mesh filename="package://articulated_arm_description/meshes/end_effector/AR_LinkScuadra_black.stl" scale="0.001 0.001 0.001"/>
      </geometry>
      <material name="Gazebo/Grey">
        <color rgba="0. 0. 0. 1"/>
      </material>
    </visual>
    <collision>
      <origin rpy="0 0 0" xyz="0 0 0"/>
      <geometry>
        <mesh filename="package://articulated_arm_description/meshes/simplified/SCUADRA_simpli.stl" scale="0.001 0.001 0.001"/>
      </geometry>
    </collision>
  </link>
  <gazebo reference="pal_to_hebi_adapter">
    <material>Gazebo/Grey</material>
    <selfCollide>False</selfCollide>
  </gazebo>

  <link name="camera_adapter">
    <inertial>
      <origin rpy="0 0 0" xyz="8.625E-08 -4.6583E-06 0.03145"/>
      <mass value="0.22652"/>
      <inertia ixx="0.00020005" ixy="-4.2442E-10" ixz="-2.9069E-10" iyy="0.00017832" iyz="-3.4402E-08" izz="0.00013478"/>
    </inertial>
    <visual>
      <origin rpy="0 0 0" xyz="0 0 0"/>
      <geometry>
        <mesh filename="package://articulated_arm_description/meshes/camera/AR_GRIPPERadapter.stl" scale="0.001 0.001 0.001"/>
      </geometry>
      <material name="Gazebo/Grey">
        <color rgba="0. 0. 0. 1"/>
      </material>
    </visual>
  </link>
  <gazebo reference="camera_adapter">
    <material>Gazebo/Grey</material>
    <selfCollide>False</selfCollide>
  </gazebo>

  <link name="camera_support">
    <inertial>
      <origin rpy="0 0 0" xyz="8.625E-08 -4.6583E-06 0.03145"/>
      <mass value="0.22652"/>
      <inertia ixx="0.00020005" ixy="-4.2442E-10" ixz="-2.9069E-10" iyy="0.00017832" iyz="-3.4402E-08" izz="0.00013478"/>
    </inertial>
    <visual>
      <origin rpy="0 0 0" xyz="0 0 0"/>
      <geometry>
        <mesh filename="package://articulated_arm_description/meshes/camera/AR_CAMERAadapter.stl" scale="0.001 0.001 0.001"/>
      </geometry>
      <material name="Gazebo/Grey">
        <color rgba="0. 0. 0. 1"/>
      </material>
    </visual>
  </link>
  <gazebo reference="camera_support">
    <material>Gazebo/Grey</material>
    <selfCollide>False</selfCollide>
  </gazebo>

  <link name="camera1">
    <inertial>
      <origin rpy="0 0 0" xyz="8.625E-08 -4.6583E-06 0.03145"/>
      <mass value="0.22652"/>
      <inertia ixx="0.00020005" ixy="-4.2442E-10" ixz="-2.9069E-10" iyy="0.00017832" iyz="-3.4402E-08" izz="0.00013478"/>
    </inertial>
    <visual>
      <origin rpy="0 0 0" xyz="0 0 0"/>
      <geometry>
        <mesh filename="package://articulated_arm_description/meshes/camera/AR_CAMERA_black.stl" scale="0.001 0.001 0.001"/>
      </geometry>
    </visual>
    <collision>
      <origin rpy="0 0 0" xyz="0 0 0"/>
      <geometry>
        <mesh filename="package://articulated_arm_description/meshes/simplified/CAMERA_simpli.stl" scale="0.001 0.001 0.001"/>
      </geometry>
    </collision>
  </link>
  <gazebo reference="camera1">
    <material>Gazebo/Black</material>
    <selfCollide>False</selfCollide>
  </gazebo>

  <link name="camera1_point"></link>


  <link name="robotiq_arg2f_base_link">
    <inertial>
      <origin xyz="8.625E-08 -4.6583E-06 0.03145" rpy="0 0 0" />
      <mass value="0.22652" />
      <inertia ixx="0.00020005" ixy="-4.2442E-10" ixz="-2.9069E-10" iyy="0.00017832" iyz="-3.4402E-08" izz="0.00013478" />
    </inertial>
    <visual>
      <origin xyz="0 0 0" rpy="0 0 0" />
      <geometry>
        <mesh filename="package://robotiq_arg2f_model_visualization/meshes/GRIPPER_base_axis.stl" scale="0.001 0.001 0.001"/>
      </geometry>
      <material name="">
        <color rgba="0.1 0.1 0.1 1" />
      </material>
    </visual>
    <collision>
      <origin xyz="0 0 0" rpy="0 0 0" />
      <geometry>
        <mesh filename="package://robotiq_arg2f_model_visualization/meshes/GRIPPER_base_axis.stl" scale="0.001 0.001 0.001"/>
      </geometry>
    </collision>
  </link>
  <gazebo reference="robotiq_arg2f_base_link">
    <material>Gazebo/Grey</material>
    <selfCollide>False</selfCollide>
  </gazebo>

  <link name="left_outer_knuckle">
    <inertial>
      <origin xyz="-0.000200000000003065 0.0199435877845359 0.0292245259211331" rpy="0 0 0" />
      <mass value="0.00853198276973456" />
      <inertia
          ixx="2.89328108496468E-06"
          ixy="-1.57935047237397E-19"
          ixz="-1.93980378593255E-19"
          iyy="1.86719750325683E-06"
          iyz="-1.21858577871576E-06"
          izz="1.21905238907251E-06" />
    </inertial>
    <visual>
      <origin xyz="0 0 0" rpy="0 0 0" />
      <geometry>
        <mesh filename="package://robotiq_arg2f_model_visualization/meshes/robotiq_arg2f_140_outer_knuckle.stl" />
      </geometry>
      <material name="">
        <color rgba="0.792156862745098 0.819607843137255 0.933333333333333 1" />
      </material>
    </visual>
    <collision>
      <origin xyz="0 0 0" rpy="0 0 0" />
      <geometry>
        <mesh filename="package://robotiq_arg2f_model_visualization/meshes/robotiq_arg2f_140_outer_knuckle.stl" />
      </geometry>
    </collision>
  </link>
  <gazebo reference="left_outer_knuckle">
    <material>Gazebo/Grey</material>
    <selfCollide>False</selfCollide>
  </gazebo>

  <link name="right_outer_knuckle">
    <inertial>
      <origin xyz="-0.000200000000003065 0.0199435877845359 0.0292245259211331" rpy="0 0 0" />
      <mass value="0.00853198276973456" />
      <inertia
          ixx="2.89328108496468E-06"
          ixy="-1.57935047237397E-19"
          ixz="-1.93980378593255E-19"
          iyy="1.86719750325683E-06"
          iyz="-1.21858577871576E-06"
          izz="1.21905238907251E-06" />
    </inertial>
    <visual>
      <origin xyz="0 0 0" rpy="0 0 0" />
      <geometry>
        <mesh filename="package://robotiq_arg2f_model_visualization/meshes/robotiq_arg2f_140_outer_knuckle.stl" />
      </geometry>
      <material name="">
        <color rgba="0.792156862745098 0.819607843137255 0.933333333333333 1" />
      </material>
    </visual>
    <collision>
      <origin xyz="0 0 0" rpy="0 0 0" />
      <geometry>
        <mesh filename="package://robotiq_arg2f_model_visualization/meshes/robotiq_arg2f_140_outer_knuckle.stl" />
      </geometry>
    </collision>
  </link>
  <gazebo reference="right_outer_knuckle">
    <material>Gazebo/Grey</material>
    <selfCollide>False</selfCollide>
  </gazebo>

  <link name="left_inner_knuckle">
    <inertial>
      <origin xyz="0.000123011831763771 0.0507850843201817 0.00103968640075166" rpy="0 0 0" />
      <mass value="0.0271177346495152" />
      <inertia
          ixx="2.61910379223783E-05"
          ixy="-2.43616858946494E-07"
          ixz="-6.37789906117123E-09"
          iyy="2.8270243746167E-06"
          iyz="-5.37200748039765E-07"
          izz="2.83695868220296E-05" />
    </inertial>
    <visual>
      <origin xyz="0 0 0" rpy="0 0 0" />
      <geometry>
        <mesh filename="package://robotiq_arg2f_model_visualization/meshes/robotiq_arg2f_140_inner_knuckle.stl" />
      </geometry>
      <material name="">
        <color rgba="0.1 0.1 0.1 1" />
      </material>
    </visual>
    <collision>
      <origin xyz="0 0 0" rpy="0 0 0" />
      <geometry>
        <mesh filename="package://robotiq_arg2f_model_visualization/meshes/robotiq_arg2f_140_inner_knuckle.stl" />
      </geometry>
    </collision>
  </link>
  <gazebo reference="left_inner_knuckle">
    <material>Gazebo/Grey</material>
    <selfCollide>False</selfCollide>
  </gazebo>

  <link name="right_inner_knuckle">
    <inertial>
      <origin xyz="0.000123011831763771 0.0507850843201817 0.00103968640075166" rpy="0 0 0" />
      <mass value="0.0271177346495152" />
      <inertia
          ixx="2.61910379223783E-05"
          ixy="-2.43616858946494E-07"
          ixz="-6.37789906117123E-09"
          iyy="2.8270243746167E-06"
          iyz="-5.37200748039765E-07"
          izz="2.83695868220296E-05" />
    </inertial>
    <visual>
      <origin xyz="0 0 0" rpy="0 0 0" />
      <geometry>
        <mesh filename="package://robotiq_arg2f_model_visualization/meshes/robotiq_arg2f_140_inner_knuckle.stl" />
      </geometry>
      <material name="">
        <color rgba="0.1 0.1 0.1 1" />
      </material>
    </visual>
    <collision>
      <origin xyz="0 0 0" rpy="0 0 0" />
      <geometry>
        <mesh filename="package://robotiq_arg2f_model_visualization/meshes/robotiq_arg2f_140_inner_knuckle.stl" />
      </geometry>
    </collision>
  </link>
  <gazebo reference="right_inner_knuckle">
    <material>Gazebo/Grey</material>
    <selfCollide>False</selfCollide>
  </gazebo>

  <link name="left_inner_finger">
    <inertial>
      <origin xyz="0.000299999999999317 0.0160078233491243 -0.0136945669206257" rpy="0 0 0" />
      <mass value="0.0104003125914103" />
      <inertia
          ixx="2.71909453810972E-06"
          ixy="1.35402465472579E-21"
          ixz="-7.1817349065269E-22"
          iyy="7.69100314106116E-07"
          iyz="6.74715432769696E-07"
          izz="2.30315190420171E-06" />
    </inertial>
    <visual>
      <origin xyz="0 0 0" rpy="0 0 0" />
      <geometry>
        <mesh filename="package://robotiq_arg2f_model_visualization/meshes/robotiq_arg2f_140_inner_finger.stl" />
      </geometry>
      <material name="">
        <color rgba="0.1 0.1 0.1 1" />
      </material>
    </visual>
    <collision>
      <origin xyz="0 0 0" rpy="0 0 0" />
      <geometry>
        <mesh filename="package://robotiq_arg2f_model_visualization/meshes/robotiq_arg2f_140_inner_finger.stl" />
      </geometry>
    </collision>
  </link>
  <gazebo reference="left_inner_finger">
    <material>Gazebo/Grey</material>
    <selfCollide>False</selfCollide>
  </gazebo>

  <link name="right_inner_finger">
    <inertial>
      <origin xyz="0.000299999999999317 0.0160078233491243 -0.0136945669206257" rpy="0 0 0" />
      <mass value="0.0104003125914103" />
      <inertia
          ixx="2.71909453810972E-06"
          ixy="1.35402465472579E-21"
          ixz="-7.1817349065269E-22"
          iyy="7.69100314106116E-07"
          iyz="6.74715432769696E-07"
          izz="2.30315190420171E-06" />
    </inertial>
    <visual>
      <origin xyz="0 0 0" rpy="0 0 0" />
      <geometry>
        <mesh filename="package://robotiq_arg2f_model_visualization/meshes/robotiq_arg2f_140_inner_finger.stl" />
      </geometry>
      <material name="">
        <color rgba="0.1 0.1 0.1 1" />
      </material>
    </visual>
    <collision>
      <origin xyz="0 0 0" rpy="0 0 0" />
      <geometry>
        <mesh filename="package://robotiq_arg2f_model_visualization/meshes/robotiq_arg2f_140_inner_finger.stl" />
      </geometry>
    </collision>
  </link>
  <gazebo reference="right_inner_finger">
    <material>Gazebo/Grey</material>
    <selfCollide>False</selfCollide>
  </gazebo>

  <link name="left_outer_finger">
    <inertial>
      <origin xyz="0.00030115855001899 0.0373907951953854 -0.0208027427000385" rpy="0 0 0" />
      <mass value="0.022614240507152" />
      <inertia
          ixx="1.52518312458174E-05"
          ixy="9.76583423954399E-10"
          ixz="-5.43838577022588E-10"
          iyy="6.17694243867776E-06"
          iyz="6.78636130740228E-06"
          izz="1.16494917907219E-05" />
    </inertial>
    <visual>
      <origin xyz="0 0 0" rpy="0 0 0" />
      <geometry>
        <mesh filename="package://robotiq_arg2f_model_visualization/meshes/robotiq_arg2f_140_outer_finger.stl" />
      </geometry>
      <material name="">
        <color rgba="0.1 0.1 0.1 1" />
      </material>
    </visual>
    <collision>
      <origin xyz="0 0 0" rpy="0 0 0" />
      <geometry>
        <mesh filename="package://robotiq_arg2f_model_visualization/meshes/robotiq_arg2f_140_outer_finger.stl" />
      </geometry>
    </collision>
  </link>
  <gazebo reference="left_outer_finger">
    <material>Gazebo/Grey</material>
    <selfCollide>False</selfCollide>
  </gazebo>

  <link name="right_outer_finger">
    <inertial>
      <origin xyz="0.00030115855001899 0.0373907951953854 -0.0208027427000385" rpy="0 0 0" />
      <mass value="0.022614240507152" />
      <inertia
          ixx="1.52518312458174E-05"
          ixy="9.76583423954399E-10"
          ixz="-5.43838577022588E-10"
          iyy="6.17694243867776E-06"
          iyz="6.78636130740228E-06"
          izz="1.16494917907219E-05" />
    </inertial>
    <visual>
      <origin xyz="0 0 0" rpy="0 0 0" />
      <geometry>
        <mesh filename="package://robotiq_arg2f_model_visualization/meshes/robotiq_arg2f_140_outer_finger.stl" />
      </geometry>
      <material name="">
        <color rgba="0.1 0.1 0.1 1" />
      </material>
    </visual>
    <collision>
      <origin xyz="0 0 0" rpy="0 0 0" />
      <geometry>
        <mesh filename="package://robotiq_arg2f_model_visualization/meshes/robotiq_arg2f_140_outer_finger.stl" />
      </geometry>
    </collision>
  </link>
  <gazebo reference="right_outer_finger">
    <material>Gazebo/Grey</material>
    <selfCollide>False</selfCollide>
  </gazebo>

  <link name="ee_link"></link>

  <joint name="world_to_base_joint" type="fixed">
    <origin rpy="0 0 0" xyz="0 0 0"/>
    <parent link="world"/>
    <child link="base_link"/>
  </joint>
  <joint name="world_to_base_screws_joint" type="fixed">
    <origin rpy="0 0 0" xyz="0 0 0"/>
    <parent link="world"/>
    <child link="scara_e1_base_screws"/>
  </joint>

  <joint name="base_to_hans1_elbow_joint" type="fixed">
    <origin rpy="0 0 0" xyz="0 0.034211319 0.048204713"/>
    <parent link="articulated_arm_hans"/>
    <child link="articulated_arm_hans_elbow"/>
  </joint>

  <joint name="motor1" type="revolute">
    <origin rpy="0 0 -1.57" xyz="0 0 0.11949"/>
    <parent link="base_link"/>
    <child link="articulated_arm_hans"/>
    <axis xyz="0 0 1"/>
    <limit effort="10" lower="-3.1416" upper="3.1416" velocity="10.0"/>
    <dynamics damping="0" friction="0"/>
  </joint>

  <joint name="motor2" type="revolute">
    <origin rpy="0 0 0" xyz="0 -0.077461260 0.045503403"/>
    <parent link="articulated_arm_hans"/>
    <child link="arm_link"/>
    <axis xyz="0 1 0"/>
    <limit effort="10" lower="-3.1416" upper="3.1416" velocity="10.0"/>
    <dynamics damping="0" friction="0"/>
  </joint>

  <joint name="arm_link_to_arm_link_arm" type="fixed">
    <origin rpy="0 0 0" xyz="0 -0.0085 0.11"/>
    <parent link="arm_link"/>
    <child link="arm_link_arm"/>
  </joint>

  <joint name="arm_link_arm_to_arm_link_paladapter" type="fixed">
    <origin rpy="0 0 0" xyz="0 0.0085 0.11"/>
    <parent link="arm_link_arm"/>
    <child link="arm_link_paladapter"/>
  </joint>

  <joint name="pal_motor_to_pal_adapter" type="fixed">
    <origin rpy="0 0 0" xyz="0 0.042900 0"/>
    <parent link="arm_link_paladapter"/>
    <child link="pal_motor"/>
  </joint>

  <joint name="pal_motor_to_pal_motor2" type="fixed">
    <origin rpy="0 0 0" xyz="0 0.0 0"/>
    <parent link="pal_motor"/>
    <child link="pal_motor2"/>
  </joint>

  <joint name="motor3" type="revolute">
    <origin rpy="0 0 0" xyz="0 0.034900 0"/>
    <parent link="pal_motor2"/>
    <child link="pal_motor_adapter"/>
    <axis xyz="0 1 0"/>
    <limit effort="10" lower="-3.1416" upper="3.1416" velocity="10.0"/>
    <dynamics damping="0" friction="0"/>
  </joint>

  <joint name="adapter_to_link" type="fixed">
    <origin rpy="0 0 0" xyz="0.110 0 0 "/>
    <parent link="pal_motor_adapter"/>
    <child link="pal_link_adapter"/>
  </joint>

  <joint name="link_to_adapter_hebi" type="fixed">
    <origin rpy="0 0 0" xyz="0.110 0 0 "/>
    <parent link="pal_link_adapter"/>
    <child link="adapter_hebi"/>
  </joint>

  <joint name="adapter_to_hebi_black" type="fixed">
    <origin rpy="0 0 0" xyz="0.0 -0.026025003 -0.025319"/>
    <parent link="adapter_hebi"/>
    <child link="hebi_black"/>
  </joint>

  <joint name="hebi_black_to_hebi_red" type="fixed">
    <origin rpy="0 0 0" xyz="0 0 0"/>
    <parent link="hebi_black"/>
    <child link="hebi_red"/>
  </joint>

  <joint name="motor4" type="revolute">
    <origin rpy="0 0 -3.1416" xyz="0 -0.026025003 0.025319"/>
    <parent link="hebi_red"/>
    <child link="hebi_adapter"/>
    <axis xyz="0 1 0"/>
    <limit effort="10" lower="-3.1416" upper="3.1416" velocity="10.0"/>
    <dynamics damping="0" friction="0"/>
  </joint>

  <joint name="hebi_adapter_to_link" type="fixed">
    <origin rpy="0 0 -3.1416" xyz="-0.0165 -0.080 0"/>
    <parent link="hebi_adapter"/>
    <child link="end_effector_adapter"/>
  </joint>

  <joint name="ee_link_joint" type="fixed">
    <origin rpy="0 0 3.14" xyz="0.290 0 0"/>
    <parent link="end_effector_adapter"/>
    <child link="ee_link"/>
  </joint>

  <joint name="end_efector_to_camera_adapter" type="fixed">
    <origin rpy="0 0 0" xyz="0.09225 0.017 0.0"/>
    <parent link="end_effector_adapter"/>
    <child link="camera_adapter"/>
  </joint>

  <joint name="camera_adapter_to_camera_support" type="fixed">
    <origin rpy="0 0 0" xyz="0.003454156 0.0 0.038280404"/>
    <parent link="camera_adapter"/>
    <child link="camera_support"/>
  </joint>

  <joint name="camera_adapter_to_camera" type="fixed">
    <origin rpy="0 0 0" xyz="0.025145844 0.0 0.038280404"/>
    <parent link="camera_support"/>
    <child link="camera1"/>
  </joint>

  <joint name="camera_to_camera_point" type="fixed">
    <origin rpy="0 0 0" xyz="0.02215 0.0 0.01275"/>
    <parent link="camera1"/>
    <child link="camera1_point"/>
  </joint>

  <joint name="end_effector_adapter_to_robotiq" type="fixed">
    <origin rpy="1.57 0 1.57 " xyz="0.02139 0 0.0"/>
    <parent link="camera_adapter"/>
    <child link="robotiq_arg2f_base_link"/>
  </joint>

  <joint name="left_outer_knuckle_joint" type="revolute">
    <origin xyz="0.030601 0 0.050905" rpy="2.29579632679 0 1.57" />
    <parent link="robotiq_arg2f_base_link" />
    <child link="left_outer_knuckle" />
    <axis xyz="-1 0 0" />
    <limit lower="0" upper="2" velocity="0.0" effort="0" />
  </joint>

  <joint name="right_outer_knuckle_joint" type="revolute">
    <origin xyz="-0.030601 0 0.050905" rpy="2.29579632679 0 4.71" />
    <parent link="robotiq_arg2f_base_link" />
    <child link="right_outer_knuckle" />
    <axis xyz="-1 0 0" />
    <limit lower="0" upper="2" velocity="0.0" effort="0" />
  </joint>

  <joint name="left_inner_knuckle_joint" type="revolute">
    <origin xyz="0.0127 0 0.05642" rpy="2.29579632679 0 1.57" />
    <parent link="robotiq_arg2f_base_link" />
    <child link="left_inner_knuckle" />
    <axis xyz="-1 0 0" />
    <limit lower="0" upper="0.7" velocity="0.1" effort="100" />
  </joint>

  <joint name="right_inner_knuckle_joint" type="revolute">
    <origin xyz="-0.0127 0 0.05642" rpy="2.29579632679 0 4.71" />
    <parent link="robotiq_arg2f_base_link" />
    <child link="right_inner_knuckle" />
    <axis xyz="-1 0 0" />
    <limit lower="0" upper="0.7" velocity="0.1" effort="100" />
  </joint>

  <joint name="left_outer_finger_joint" type="revolute">
    <origin xyz="0 0.01821998610742 0.0260018192872234" rpy="0 0 0" />
    <parent link="left_outer_knuckle" />
    <child link="left_outer_finger" />
    <axis xyz="-1 0 0" />
    <limit lower="-2" upper="2" velocity="2.0" effort="1000" />
  </joint>

  <joint name="right_outer_finger_joint" type="revolute">
    <origin xyz="0 0.01821998610742 0.0260018192872234" rpy="0 0 0" />
    <parent link="right_outer_knuckle" />
    <child link="right_outer_finger" />
    <axis xyz="-1 0 0" />
    <limit lower="-2" upper="2" velocity="2.0" effort="1000" />
  </joint>

  <joint name="left_inner_finger_joint" type="revolute">
    <origin xyz="0 0.0817554015893473 -0.0282203446692936" rpy="-.725 0 0" />
    <parent link="left_outer_finger" />
    <child link="left_inner_finger" />
    <axis xyz="-1 0 0" />
    <limit lower="-2" upper="2" velocity="2.0" effort="1000" />
  </joint>

  <joint name="right_inner_finger_joint" type="revolute">
    <origin xyz="0 0.0817554015893473 -0.0282203446692936" rpy="-.725 0 0" />
    <parent link="right_outer_finger" />
    <child link="right_inner_finger" />
    <axis xyz="-1 0 0" />
    <limit lower="-2" upper="2" velocity="2.0" effort="1000" />
  </joint>

  <gazebo>
    <joint name="left_inner_finger_knuckle_joint" type="revolute">
      <pose frame="">0 0.006 -0.018 0 0 0</pose>
      <parent>robot::left_inner_knuckle</parent>
      <child>robot::left_inner_finger</child>
      <axis>
        <xyz>0 0 -1</xyz>
        <limit>
          <lower>-0.6</lower>
          <upper>0.6</upper>
          <velocity>0</velocity>
          <effort>0</effort>
        </limit>
      </axis>
    </joint>

    <joint name="right_inner_finger_knuckle_joint" type="revolute">
      <pose frame="">0 0.006 -0.018 0 0 0</pose>
      <parent>robot::right_inner_knuckle</parent>
      <child>robot::right_inner_finger</child>
      <axis>
        <xyz>0 0 -1</xyz>
        <limit>
          <lower>-0.6</lower>
          <upper>0.6</upper>
          <velocity>0</velocity>
          <effort>0</effort>
        </limit>
      </axis>
    </joint>

    <plugin filename="libRobotiq140Plugin.so" name="robotiq_arg2f_gazebo_plugins"/>
    <plugin filename="libgazebo_grasp_fix.so" name="gazebo_grasp_fix">
      <arm>
        <arm_name>robot</arm_name>
        <palm_link>left_inner_finger</palm_link>
        <gripper_link>left_inner_finger</gripper_link>
        <gripper_link>right_inner_finger</gripper_link>
        <gripper_link>left_inner_knuckle</gripper_link>
        <gripper_link>right_inner_knuckle</gripper_link>
      </arm>
      <forces_angle_tolerance>100</forces_angle_tolerance>
      <update_rate>4</update_rate>
      <grip_count_threshold>4</grip_count_threshold>
      <max_grip_count>8</max_grip_count>
      <release_tolerance>0.5</release_tolerance>
      <disable_collisions_on_attach>false</disable_collisions_on_attach>
      <contact_topic>__default_topic__</contact_topic>
   </plugin>
  </gazebo>

  <transmission name="motor1_trans">
    <type>transmission_interface/SimpleTransmission</type>
    <joint name="motor1">
      <hardwareInterface>PositionJointInterface</hardwareInterface>
    </joint>
    <actuator name="motor1_motor">
      <mechanicalReduction>1</mechanicalReduction>
    </actuator>
  </transmission>
  <transmission name="motor2_trans">
    <type>transmission_interface/SimpleTransmission</type>
    <joint name="motor2">
      <hardwareInterface>PositionJointInterface</hardwareInterface>
    </joint>
    <actuator name="motor2_motor">
      <mechanicalReduction>1</mechanicalReduction>
    </actuator>
  </transmission>
  <transmission name="motor3_trans">
    <type>transmission_interface/SimpleTransmission</type>
    <joint name="motor3">
      <hardwareInterface>PositionJointInterface</hardwareInterface>
    </joint>
    <actuator name="motor3_motor">
      <mechanicalReduction>1</mechanicalReduction>
    </actuator>
  </transmission>
  <transmission name="motor4_trans">
    <type>transmission_interface/SimpleTransmission</type>
    <joint name="motor4">
      <hardwareInterface>PositionJointInterface</hardwareInterface>
    </joint>
    <actuator name="motor4_motor">
      <mechanicalReduction>1</mechanicalReduction>
    </actuator>
  </transmission>

  <gazebo>
    <plugin filename="libgazebo_ros_control.so" name="gazebo_ros_control">
      <robotNamespace>/</robotNamespace>
      <robotSimType>gazebo_ros_control/DefaultRobotHWSim</robotSimType>
    </plugin>
  </gazebo>

  <gazebo reference="camera1_point">
    <sensor type="camera" name="camera1">
      <update_rate>30.0</update_rate>
      <camera name="head">
        <horizontal_fov>1.3962634</horizontal_fov>
        <image>
          <width>640</width>
          <height>480</height>
          <format>R8G8B8</format>
        </image>
        <clip>
          <near>0.02</near>
          <far>300</far>
        </clip>
        <noise>
          <type>gaussian</type>
          <!-- Noise is sampled independently per pixel on each frame.
               That pixel's noise value is added to each of its color
               channels, which at that point lie in the range [0,1]. -->
          <mean>0.0</mean>
          <stddev>0.007</stddev>
        </noise>
        <visualize>true</visualize>
      </camera>
      <plugin name="camera_controller" filename="libgazebo_ros_camera.so">
        <alwaysOn>true</alwaysOn>
        <updateRate>30.0</updateRate>
        <cameraName>articulated_arm/camera1</cameraName>
        <imageTopicName>image_raw</imageTopicName>
        <cameraInfoTopicName>camera_info</cameraInfoTopicName>
        <frameName>camera_link</frameName>
        <hackBaseline>0.07</hackBaseline>
        <distortionK1>0.0</distortionK1>
        <distortionK2>0.0</distortionK2>
        <distortionK3>0.0</distortionK3>
        <distortionT1>0.0</distortionT1>
        <distortionT2>0.0</distortionT2>
      </plugin>
    </sensor>
  </gazebo>

</robot>
