<?xml version="1.0" encoding="utf-8"?>
<mujoco>
	<compiler angle="radian" coordinate="local" meshdir="../stls/fetch" texturedir="../textures"></compiler>
	<option timestep="0.002">
		<flag warmstart="enable"></flag>
	</option>

	<include file="shared.xml"></include>
	
	<worldbody>
		<geom name="floor0" pos="0.8 0.75 0" size="0.75 0.7 1" type="plane" condim="3" material="material1"></geom>
		<body name="floor0" pos="0.8 0.75 0">
			<site name="target0" pos="0 0 0.5" size="0.02 0.02 0.02" rgba="1 0 0 1" type="sphere"></site>
		</body>

		<include file="robot.xml"></include>
		
		<body pos="0.25 0.35 0.2" name="table_table20:table_table20">
			<geom size="0.25 0.35 0.2" type="box" mass="2000" rgba="1.5 1.5 1.5 1"></geom>
			<joint name="table_table20:slide0" type="slide" axis="1 0 0" damping="10000" pos="0 0 0"></joint>
			<joint name="table_table20:slide1" type="slide" axis="0 1 0" damping="10000" pos="0 0 0"></joint>
			<joint name="table_table20:slide2" type="slide" axis="0 0 1" damping="10000" pos="0 0 0"></joint>
		</body>
	</worldbody>
	
	<actuator></actuator>
</mujoco>
