<?xml version="1.0"?>
<robot name="scara_e1_3joints" xmlns:xacro="http://ros.org/wiki/xacro">

  <link name="world">
     <visual>
       <geometry>
         <box size="1.5 0.8 0.001" />
       </geometry>
       <origin rpy="0 0 0" xyz="0 0 0"/>
       <material name="Gazebo/Black">
       </material>
     </visual>
  </link>

  <link name="scara_e1_base_link">
    <inertial>
      <origin xyz="0 0 0" rpy="0 0 0" />
      <mass value="0.22652" />
      <inertia ixx="1.0" ixy="0.0" ixz="0.0" iyy="1.0" iyz="0.0" izz="1.0"/>
    </inertial>
    <visual>
      <origin xyz="0 0 0" rpy="0 0 0" />
      <geometry>
        <mesh scale="0.001 0.001 0.001" filename="package://scara_e1_description/meshes/scara_e1_base_link.stl" />
      </geometry>
      <material name="Gazebo/Grey">
        <color rgba="0. 0. 0. 1" />
      </material>
    </visual>
    <collision>
      <origin xyz="0 0 0" rpy="0 0 0" />
      <geometry>
        <mesh scale="0.001 0.001 0.001" filename="package://scara_e1_description/meshes/scara_e1_base_link.stl" />
      </geometry>
    </collision>
  </link>

  <link name="scara_e1_metraquilato">
    <inertial>
      <origin xyz="0 0 0" rpy="0 0 0" />
      <mass value="0.22652" />
      <inertia ixx="1.0" ixy="0.0" ixz="0.0" iyy="1.0" iyz="0.0" izz="1.0"/>
    </inertial>
    <visual>
      <origin xyz="0 0 0" rpy="0 0 0" />
      <geometry>
        <mesh scale="0.001 0.001 0.001" filename="package://scara_e1_description/meshes/scara_e1_metacrilato.stl" />
      </geometry>
      <material name="Gazebo/Black">
        <color rgba="0. 0. 0. 1" />
      </material>
    </visual>
    <collision>
      <origin xyz="0 0 0" rpy="0 0 0" />
      <geometry>
        <mesh scale="0.001 0.001 0.001" filename="package://scara_e1_description/meshes/scara_e1_metacrilato.stl" />
      </geometry>
    </collision>
  </link>

  <link name="scara_e1_hros_logo">
    <inertial>
      <origin xyz="0 0 0" rpy="0 0 0" />
      <mass value="0.22652" />
      <inertia ixx="1.0" ixy="0.0" ixz="0.0" iyy="1.0" iyz="0.0" izz="1.0"/>
    </inertial>
    <visual>
      <origin xyz="0 0 0" rpy="0 0 0" />
      <geometry>
        <mesh scale="0.001 0.001 0.001" filename="package://scara_e1_description/meshes/scara_e1_hros_logo.stl" />
      </geometry>
      <material name="Gazebo/Black">
        <color rgba="0. 0. 0. 1" />
      </material>
    </visual>
    <collision>
      <origin xyz="0 0 0" rpy="0 0 0" />
      <geometry>
        <mesh scale="0.001 0.001 0.001" filename="package://scara_e1_description/meshes/scara_e1_hros_logo.stl" />
      </geometry>
    </collision>
  </link>

  <link name="scara_e1_base_motor">
    <inertial>
      <origin xyz="0 0 0" rpy="0 0 0" />
      <mass value="0.22652" />
      <inertia ixx="1.0" ixy="0.0" ixz="0.0" iyy="1.0" iyz="0.0" izz="1.0"/>
    </inertial>
    <visual>
      <origin xyz="0 0 0" rpy="0 0 0" />
      <geometry>
        <mesh scale="0.001 0.001 0.001" filename="package://scara_e1_description/meshes/scara_e1_base_motor.stl" />
      </geometry>
      <material name="Gazebo/Grey">
        <color rgba="0. 0. 0. 1" />
      </material>
    </visual>
    <collision>
      <origin xyz="0 0 0" rpy="0 0 0" />
      <geometry>
        <mesh scale="0.001 0.001 0.001" filename="package://scara_e1_description/meshes/scara_e1_base_motor.stl" />
      </geometry>
    </collision>
  </link>

  <link name="scara_e1_motor1">
    <inertial>
      <origin xyz="0 0 0" rpy="0 0 0" />
      <mass value="0.22652" />
      <inertia ixx="1.0" ixy="0.0" ixz="0.0" iyy="1.0" iyz="0.0" izz="1.0"/>
    </inertial>
    <visual>
      <origin xyz="0 0 0" rpy="0 0 0" />
      <geometry>
        <mesh scale="0.001 0.001 0.001" filename="package://scara_e1_description/meshes/HEBImotor_case.stl" />
      </geometry>
      <material name="Gazebo/Red">
        <color rgba="0. 0. 0. 1" />
      </material>
    </visual>
    <collision>
      <origin xyz="0 0 0" rpy="0 0 0" />
      <geometry>
        <mesh scale="0.001 0.001 0.001" filename="package://scara_e1_description/meshes/HEBImotor_case.stl" />
      </geometry>
    </collision>
  </link>

  <link name="scara_e1_motor1_inside">
    <inertial>
      <origin xyz="0 0 0" rpy="0 0 0" />
      <mass value="0.22652" />
      <inertia ixx="1.0" ixy="0.0" ixz="0.0" iyy="1.0" iyz="0.0" izz="1.0"/>
    </inertial>
    <visual>
      <origin xyz="0 0 0" rpy="0 0 0" />
      <geometry>
        <mesh scale="0.001 0.001 0.001" filename="package://scara_e1_description/meshes/HEBImotor.stl" />
      </geometry>
      <material name="Gazebo/Red">
        <color rgba="0. 0. 0. 1" />
      </material>
    </visual>
    <collision>
      <origin xyz="0 0 0" rpy="0 0 0" />
      <geometry>
        <mesh scale="0.001 0.001 0.001" filename="package://scara_e1_description/meshes/HEBImotor.stl" />
      </geometry>
    </collision>
  </link>

  <link name="scara_e1_motor1_support">
    <inertial>
      <origin xyz="0 0 0" rpy="0 0 0" />
      <mass value="0.22652" />
      <inertia ixx="1.0" ixy="0.0" ixz="0.0" iyy="1.0" iyz="0.0" izz="1.0"/>
    </inertial>
    <visual>
      <origin xyz="0 0 0" rpy="0 0 0" />
      <geometry>
        <mesh scale="0.001 0.001 0.001" filename="package://scara_e1_description/meshes/HEBImotor_support.stl" />
      </geometry>
      <material name="Gazebo/Grey">
        <color rgba="0. 0. 0. 1" />
      </material>
    </visual>
    <collision>
      <origin xyz="0 0 0" rpy="0 0 0" />
      <geometry>
        <mesh scale="0.001 0.001 0.001" filename="package://scara_e1_description/meshes/HEBImotor_support.stl" />
      </geometry>
    </collision>
  </link>

  <link name="scara_e1_bar1">
    <inertial>
      <origin xyz="0 0 0" rpy="0 0 0" />
      <mass value="0.22652" />
      <inertia ixx="1.0" ixy="0.0" ixz="0.0" iyy="1.0" iyz="0.0" izz="1.0"/>
    </inertial>
    <visual>
      <origin xyz="0 0 0" rpy="0 0 0" />
      <geometry>
        <mesh scale="0.001 0.001 0.001" filename="package://scara_e1_description/meshes/scara_bar.stl" />
      </geometry>
      <material name="Gazebo/White">
        <color rgba="0. 0. 0. 1" />
      </material>
    </visual>
    <collision>
      <origin xyz="0 0 0" rpy="0 0 0" />
      <geometry>
        <mesh scale="0.001 0.001 0.001" filename="package://scara_e1_description/meshes/scara_bar.stl" />
      </geometry>
    </collision>
  </link>

  <link name="scara_e1_fixbar1">
    <inertial>
      <origin xyz="0 0 0" rpy="0 0 0" />
      <mass value="0.22652" />
      <inertia ixx="1.0" ixy="0.0" ixz="0.0" iyy="1.0" iyz="0.0" izz="1.0"/>
    </inertial>
    <visual>
      <origin xyz="0 0 0" rpy="0 0 0" />
      <geometry>
        <mesh scale="0.001 0.001 0.001" filename="package://scara_e1_description/meshes/HEBImotor_fixbar.stl" />
      </geometry>
      <material name="Gazebo/Grey">
        <color rgba="0. 0. 0. 1" />
      </material>
    </visual>
    <collision>
      <origin xyz="0 0 0" rpy="0 0 0" />
      <geometry>
        <mesh scale="0.001 0.001 0.001" filename="package://scara_e1_description/meshes/HEBImotor_fixbar.stl" />
      </geometry>
    </collision>
  </link>

  <link name="scara_e1_motor2">
    <inertial>
      <origin xyz="0 0 0" rpy="0 0 0" />
      <mass value="0.22652" />
      <inertia ixx="1.0" ixy="0.0" ixz="0.0" iyy="1.0" iyz="0.0" izz="1.0"/>
    </inertial>
    <visual>
      <origin xyz="0 0 0" rpy="0 0 0" />
      <geometry>
        <mesh scale="0.001 0.001 0.001" filename="package://scara_e1_description/meshes/HEBImotor_case.stl" />
      </geometry>
      <material name="Gazebo/Red">
        <color rgba="0. 0. 0. 1" />
      </material>
    </visual>
    <collision>
      <origin xyz="0 0 0" rpy="0 0 0" />
      <geometry>
        <mesh scale="0.001 0.001 0.001" filename="package://scara_e1_description/meshes/HEBImotor_case.stl" />
      </geometry>
    </collision>
  </link>

  <link name="scara_e1_motor2_inside">
    <inertial>
      <origin xyz="0 0 0" rpy="0 0 0" />
      <mass value="0.22652" />
      <inertia ixx="1.0" ixy="0.0" ixz="0.0" iyy="1.0" iyz="0.0" izz="1.0"/>
    </inertial>
    <visual>
      <origin xyz="0 0 0" rpy="0 0 0" />
      <geometry>
        <mesh scale="0.001 0.001 0.001" filename="package://scara_e1_description/meshes/HEBImotor.stl" />
      </geometry>
      <material name="Gazebo/Red">
        <color rgba="0. 0. 0. 1" />
      </material>
    </visual>
    <collision>
      <origin xyz="0 0 0" rpy="0 0 0" />
      <geometry>
        <mesh scale="0.001 0.001 0.001" filename="package://scara_e1_description/meshes/HEBImotor.stl" />
      </geometry>
    </collision>
  </link>

  <link name="scara_e1_motor2_support">
    <inertial>
      <origin xyz="0 0 0" rpy="0 0 0" />
      <mass value="0.22652" />
      <inertia ixx="1.0" ixy="0.0" ixz="0.0" iyy="1.0" iyz="0.0" izz="1.0"/>
    </inertial>
    <visual>
      <origin xyz="0 0 0" rpy="0 0 0" />
      <geometry>
        <mesh scale="0.001 0.001 0.001" filename="package://scara_e1_description/meshes/HEBImotor_support.stl" />
      </geometry>
      <material name="Gazebo/Grey">
        <color rgba="0. 0. 0. 1" />
      </material>
    </visual>
    <collision>
      <origin xyz="0 0 0" rpy="0 0 0" />
      <geometry>
        <mesh scale="0.001 0.001 0.001" filename="package://scara_e1_description/meshes/HEBImotor_support.stl" />
      </geometry>
    </collision>
  </link>

  <link name="scara_e1_bar2">
    <inertial>
      <origin xyz="0 0 0" rpy="0 0 0" />
      <mass value="0.22652" />
      <inertia ixx="1.0" ixy="0.0" ixz="0.0" iyy="1.0" iyz="0.0" izz="1.0"/>
    </inertial>
    <visual>
      <origin xyz="0 0 0" rpy="0 0 0" />
      <geometry>
        <mesh scale="0.001 0.001 0.001" filename="package://scara_e1_description/meshes/scara_bar.stl" />
      </geometry>
      <material name="Gazebo/White">
        <color rgba="0. 0. 0. 1" />
      </material>
    </visual>
    <collision>
      <origin xyz="0 0 0" rpy="0 0 0" />
      <geometry>
        <mesh scale="0.001 0.001 0.001" filename="package://scara_e1_description/meshes/scara_bar.stl" />
      </geometry>
    </collision>
  </link>

  <link name="scara_e1_fixbar2">
    <inertial>
      <origin xyz="0 0 0" rpy="0 0 0" />
      <mass value="0.22652" />
      <inertia ixx="1.0" ixy="0.0" ixz="0.0" iyy="1.0" iyz="0.0" izz="1.0"/>
    </inertial>
    <visual>
      <origin xyz="0 0 0" rpy="0 0 0" />
      <geometry>
        <mesh scale="0.001 0.001 0.001" filename="package://scara_e1_description/meshes/HEBImotor_fixbar.stl" />
      </geometry>
      <material name="Gazebo/Grey">
        <color rgba="0. 0. 0. 1" />
      </material>
    </visual>
    <collision>
      <origin xyz="0 0 0" rpy="0 0 0" />
      <geometry>
        <mesh scale="0.001 0.001 0.001" filename="package://scara_e1_description/meshes/HEBImotor_fixbar.stl" />
      </geometry>
    </collision>
  </link>

  <link name="scara_e1_motor3">
    <inertial>
      <origin xyz="0 0 0" rpy="0 0 0" />
      <mass value="0.22652" />
      <inertia ixx="1.0" ixy="0.0" ixz="0.0" iyy="1.0" iyz="0.0" izz="1.0"/>
    </inertial>
    <visual>
      <origin xyz="0 0 0" rpy="0 0 0" />
      <geometry>
        <mesh scale="0.001 0.001 0.001" filename="package://scara_e1_description/meshes/HEBImotor_case.stl" />
      </geometry>
      <material name="Gazebo/Red">
        <color rgba="0. 0. 0. 1" />
      </material>
    </visual>
    <collision>
      <origin xyz="0 0 0" rpy="0 0 0" />
      <geometry>
        <mesh scale="0.001 0.001 0.001" filename="package://scara_e1_description/meshes/HEBImotor_case.stl" />
      </geometry>
    </collision>
  </link>

  <link name="scara_e1_motor3_inside">
    <inertial>
      <origin xyz="0 0 0" rpy="0 0 0" />
      <mass value="0.22652" />
      <inertia ixx="1.0" ixy="0.0" ixz="0.0" iyy="1.0" iyz="0.0" izz="1.0"/>
    </inertial>
    <visual>
      <origin xyz="0 0 0" rpy="0 0 0" />
      <geometry>
        <mesh scale="0.001 0.001 0.001" filename="package://scara_e1_description/meshes/HEBImotor.stl" />
      </geometry>
      <material name="Gazebo/Red">
        <color rgba="0. 0. 0. 1" />
      </material>
    </visual>
    <collision>
      <origin xyz="0 0 0" rpy="0 0 0" />
      <geometry>
        <mesh scale="0.001 0.001 0.001" filename="package://scara_e1_description/meshes/HEBImotor.stl" />
      </geometry>
    </collision>
  </link>

  <link name="scara_e1_motor3_support">
    <inertial>
      <origin xyz="0 0 0" rpy="0 0 0" />
      <mass value="0.22652" />
      <inertia ixx="1.0" ixy="0.0" ixz="0.0" iyy="1.0" iyz="0.0" izz="1.0"/>
    </inertial>
    <visual>
      <origin xyz="0 0 0" rpy="0 0 0" />
      <geometry>
        <mesh scale="0.001 0.001 0.001" filename="package://scara_e1_description/meshes/HEBImotor_support.stl" />
      </geometry>
      <material name="Gazebo/Grey">
        <color rgba="0. 0. 0. 1" />
      </material>
    </visual>
    <collision>
      <origin xyz="0 0 0" rpy="0 0 0" />
      <geometry>
        <mesh scale="0.001 0.001 0.001" filename="package://scara_e1_description/meshes/HEBImotor_support.stl" />
      </geometry>
    </collision>
  </link>

  <link name="scara_e1_bar3">
    <inertial>
      <origin xyz="0 0 0" rpy="0 0 0" />
      <mass value="0.22652" />
      <inertia ixx="1.0" ixy="0.0" ixz="0.0" iyy="1.0" iyz="0.0" izz="1.0"/>
    </inertial>
    <visual>
      <origin xyz="0 0 0" rpy="0 0 0" />
      <geometry>
        <mesh scale="0.001 0.001 0.001" filename="package://scara_e1_description/meshes/scara_bar.stl" />
      </geometry>
      <material name="Gazebo/White">
        <color rgba="0. 0. 0. 1" />
      </material>
    </visual>
    <collision>
      <origin xyz="0 0 0" rpy="0 0 0" />
      <geometry>
        <mesh scale="0.001 0.001 0.001" filename="package://scara_e1_description/meshes/scara_bar.stl" />
      </geometry>
    </collision>
  </link>

  <link name="scara_e1_rangefinder">
    <inertial>
      <origin xyz="0 0 0" rpy="0 0 0" />
      <mass value="0.22652" />
      <inertia ixx="1.0" ixy="0.0" ixz="0.0" iyy="1.0" iyz="0.0" izz="1.0"/>
    </inertial>
    <visual>
      <origin xyz="0 0 0" rpy="0 0 0" />
      <geometry>
        <mesh scale="0.001 0.001 0.001" filename="package://scara_e1_description/meshes/scara_e1_rangefinder.stl" />
      </geometry>
      <material name="Gazebo/Blue">
        <color rgba="0. 0. 0. 1" />
      </material>
    </visual>
    <collision>
      <origin xyz="0 0 0" rpy="0 0 0" />
      <geometry>
        <mesh scale="0.001 0.001 0.001" filename="package://scara_e1_description/meshes/scara_e1_rangefinder.stl" />
      </geometry>
    </collision>
  </link>

  <link name="ee_link"/>

  <joint name="world_to_base_joint" type="fixed">
    <origin xyz="-0.7 0 0" rpy="0 0 -1.57"/>
    <parent link="world"/>
    <child link="scara_e1_base_link"/>
  </joint>

  <joint name="logo_joint" type="fixed">
    <origin xyz="-0.7 ${-0.332} 0.045" rpy="0 0 -1.57"/>
    <parent link="world"/>
    <child link="scara_e1_hros_logo"/>
  </joint>

  <joint name="base_to_metraquilato_joint" type="fixed">
    <origin xyz="-0.7 0 0" rpy="0 0 -1.57"/>
    <parent link="world"/>
    <child link="scara_e1_metraquilato"/>
  </joint>

  <joint name="base_to_base_motor_joint" type="fixed">
    <origin xyz="-0.285 0 0.08" rpy="0 0 1.57"/>
    <parent link="scara_e1_base_link"/>
    <child link="scara_e1_base_motor"/>
  </joint>

  <joint name="base_to_motor1_joint" type="fixed">
    <origin xyz="0 0. 0" rpy="0 0 0"/>
    <parent link="scara_e1_base_motor"/>
    <child link="scara_e1_motor1"/>
  </joint>

  <joint name="base_to_motor1_inside_joint" type="fixed">
    <origin xyz="0 0. 0" rpy="0 0 0"/>
    <parent link="scara_e1_motor1"/>
    <child link="scara_e1_motor1_inside"/>
  </joint>

  <joint name="motor1" type="revolute">
    <origin xyz="-0.0313 0 0.0702" rpy="0 0 1.57" />
    <parent link="scara_e1_motor1_inside" />
    <child link="scara_e1_motor1_support" />
    <axis xyz="0 0 1" />
    <limit lower="-3.1416" upper="3.1416"  velocity="10.0" effort="10" />
    <dynamics damping="0" friction="0"/>
  </joint>

  <joint name="base_to_bar1_joint" type="fixed">
    <origin xyz="-0.1155 0. 0.0240" rpy="0 0 0"/>
    <parent link="scara_e1_motor1_support"/>
    <child link="scara_e1_bar1"/>
  </joint>

  <joint name="scara_e1_fixbar1_joint" type="fixed">
    <origin xyz="-0.0783 0. 0.0180" rpy="0 0 3.14"/>
    <parent link="scara_e1_bar1"/>
    <child link="scara_e1_fixbar1"/>
  </joint>

  <joint name="base_to_motor2_joint" type="fixed">
    <origin xyz="0 0. 0" rpy="0 0 3.1416"/>
    <parent link="scara_e1_fixbar1"/>
    <child link="scara_e1_motor2"/>
  </joint>

  <joint name="base_to_motor2_inside_joint" type="fixed">
    <origin xyz="0 0. 0" rpy="0 0 0"/>
    <parent link="scara_e1_motor2"/>
    <child link="scara_e1_motor2_inside"/>
  </joint>

  <joint name="motor2" type="revolute">
    <origin xyz="-0.0313 0 0.0702" rpy="0 0 0" />
    <parent link="scara_e1_motor2_inside" />
    <child link="scara_e1_motor2_support" />
    <axis xyz="0 0 1" />
    <limit lower="-3.1416" upper="3.1416"  velocity="10.0" effort="10" />
    <dynamics damping="0" friction="0"/>
  </joint>

  <joint name="base_to_bar2_joint" type="fixed">
    <origin xyz="-0.1155 0. 0.0240" rpy="0 0 0"/>
    <parent link="scara_e1_motor2_support"/>
    <child link="scara_e1_bar2"/>
  </joint>

  <joint name="scara_e1_fixbar2_joint" type="fixed">
    <origin xyz="-0.0783 0. 0.0180" rpy="0 0 3.14"/>
    <parent link="scara_e1_bar2"/>
    <child link="scara_e1_fixbar2"/>
  </joint>

  <joint name="base_to_motor3_joint" type="fixed">
    <origin xyz="0 0. 0" rpy="0 0 3.1416"/>
    <parent link="scara_e1_fixbar2"/>
    <child link="scara_e1_motor3"/>
  </joint>

  <joint name="base_to_motor3_inside_joint" type="fixed">
    <origin xyz="0 0. 0" rpy="0 0 0"/>
    <parent link="scara_e1_motor3"/>
    <child link="scara_e1_motor3_inside"/>
  </joint>

  <joint name="motor3" type="revolute">
    <origin xyz="-0.0313 0 0.0702" rpy="0 0 0" />
    <parent link="scara_e1_motor3_inside" />
    <child link="scara_e1_motor3_support" />
    <axis xyz="0 0 1" />
    <limit lower="-3.1416" upper="3.1416"  velocity="10.0" effort="10" />
    <dynamics damping="0" friction="0"/>
  </joint>

  <joint name="base_to_bar3_joint" type="fixed">
    <origin xyz="-0.1155 0. 0.0240" rpy="0 0 0"/>
    <parent link="scara_e1_motor3_support"/>
    <child link="scara_e1_bar3"/>
  </joint>

  <joint name="rangefinder_joint" type="fixed">
    <origin xyz="-0.083 0 0.0405119" rpy="0 0 3.1416"/>
    <parent link="scara_e1_bar3"/>
    <child link="scara_e1_rangefinder"/>
  </joint>

  <joint name="ee_link_joint" type="fixed">
    <origin xyz="-0.245 0 0" rpy="0 0 0"/>
    <parent link="scara_e1_motor3_support"/>
    <child link="ee_link"/>
  </joint>

  <transmission name="motor1_trans">
    <type>transmission_interface/SimpleTransmission</type>
    <joint name="motor1">
      <hardwareInterface>PositionJointInterface</hardwareInterface>
    </joint>
    <actuator name="motor1_motor">
      <mechanicalReduction>1</mechanicalReduction>
    </actuator>
  </transmission>

  <transmission name="motor2_trans">
    <type>transmission_interface/SimpleTransmission</type>
    <joint name="motor2">
      <hardwareInterface>PositionJointInterface</hardwareInterface>
    </joint>
    <actuator name="motor2_motor">
      <mechanicalReduction>1</mechanicalReduction>
    </actuator>
  </transmission>

  <transmission name="motor3_trans">
    <type>transmission_interface/SimpleTransmission</type>
    <joint name="motor3">
      <hardwareInterface>PositionJointInterface</hardwareInterface>
    </joint>
    <actuator name="motor3_motor">
      <mechanicalReduction>1</mechanicalReduction>
    </actuator>
  </transmission>

  <gazebo reference="scara_e1_base_link">
    <material>Gazebo/Grey</material>
    <selfCollide>False</selfCollide>
  </gazebo>

  <gazebo reference="scara_e1_base_motor">
    <material>Gazebo/Grey</material>
    <selfCollide>False</selfCollide>
  </gazebo>

  <gazebo reference="scara_e1_metraquilato">
    <material>Gazebo/Black</material>
    <selfCollide>False</selfCollide>
  </gazebo>

  <gazebo reference="scara_e1_hros_logo">
    <material>Gazebo/Black</material>
    <selfCollide>False</selfCollide>
  </gazebo>

  <gazebo reference="scara_e1_motor1">
    <material>Gazebo/Black</material>
    <selfCollide>False</selfCollide>
  </gazebo>

  <gazebo reference="scara_e1_motor1_inside">
    <material>Gazebo/Red</material>
    <selfCollide>False</selfCollide>
  </gazebo>

  <gazebo reference="scara_e1_motor1_support">
    <material>Gazebo/Grey</material>
    <selfCollide>False</selfCollide>
  </gazebo>

  <gazebo reference="scara_e1_bar1">
    <material>Gazebo/White</material>
    <selfCollide>False</selfCollide>
  </gazebo>

  <gazebo reference="scara_e1_fixbar1">
    <material>Gazebo/White</material>
    <selfCollide>False</selfCollide>
  </gazebo>

  <gazebo reference="scara_e1_motor2">
    <material>Gazebo/Black</material>
    <selfCollide>False</selfCollide>
  </gazebo>

  <gazebo reference="scara_e1_motor2_inside">
    <material>Gazebo/Red</material>
    <selfCollide>False</selfCollide>
  </gazebo>

  <gazebo reference="scara_e1_motor3">
    <material>Gazebo/Black</material>
    <selfCollide>False</selfCollide>
  </gazebo>

  <gazebo reference="scara_e1_motor3_inside">
    <material>Gazebo/Red</material>
    <selfCollide>False</selfCollide>
  </gazebo>

  <gazebo reference="scara_e1_motor3_support">
    <material>Gazebo/Grey</material>
    <selfCollide>False</selfCollide>
  </gazebo>

  <gazebo reference="scara_e1_bar3">
    <material>Gazebo/White</material>
    <selfCollide>False</selfCollide>
  </gazebo>

  <gazebo reference="scara_e1_rangefinder">
    <material>Gazebo/Blue</material>
    <selfCollide>False</selfCollide>
  </gazebo>


  <link name="4_dof_scara_e1_base_link">
    <inertial>
      <origin xyz="8.625E-08 -4.6583E-06 0.03145" rpy="0 0 0" />
      <mass value="0.22652" />
      <inertia ixx="0.00020005" ixy="-4.2442E-10" ixz="-2.9069E-10" iyy="0.00017832" iyz="-3.4402E-08" izz="0.00013478" />
    </inertial>
    <visual>
      <origin xyz="0 0 0" rpy="0 0 0" />
      <geometry>
        <mesh scale="0.001 0.001 0.001" filename="package://scara_e1_description/meshes/scara_e1_base_link.stl" />
      </geometry>
      <material name="Gazebo/Grey">
        <color rgba="0. 0. 0. 1" />
      </material>
    </visual>
    <collision>
      <origin xyz="0 0 0" rpy="0 0 0" />
      <geometry>
        <mesh scale="0.001 0.001 0.001" filename="package://scara_e1_description/meshes/scara_e1_base_link.stl" />
      </geometry>
    </collision>
  </link>


  <link name="4_dof_scara_e1_metraquilato">
    <inertial>
      <origin xyz="8.625E-08 -4.6583E-06 0.03145" rpy="0 0 0" />
      <mass value="0.22652" />
      <inertia ixx="0.00020005" ixy="-4.2442E-10" ixz="-2.9069E-10" iyy="0.00017832" iyz="-3.4402E-08" izz="0.00013478" />
    </inertial>
    <visual>
      <origin xyz="0 0 0" rpy="0 0 0" />
      <geometry>
        <mesh scale="0.001 0.001 0.001" filename="package://scara_e1_description/meshes/scara_e1_metacrilato.stl" />
      </geometry>
      <material name="Gazebo/Black">
        <color rgba="0. 0. 0. 1" />
      </material>
    </visual>
    <collision>
      <origin xyz="0 0 0" rpy="0 0 0" />
      <geometry>
        <mesh scale="0.001 0.001 0.001" filename="package://scara_e1_description/meshes/scara_e1_metacrilato.stl" />
      </geometry>
    </collision>
  </link>

  <link name="4_dof_scara_e1_hros_logo">
    <inertial>
      <origin xyz="8.625E-08 -4.6583E-06 0.03145" rpy="0 0 0" />
      <mass value="0.22652" />
      <inertia ixx="0.00020005" ixy="-4.2442E-10" ixz="-2.9069E-10" iyy="0.00017832" iyz="-3.4402E-08" izz="0.00013478" />
    </inertial>
    <visual>
      <origin xyz="0 0 0" rpy="0 0 0" />
      <geometry>
        <mesh scale="0.001 0.001 0.001" filename="package://scara_e1_description/meshes/scara_e1_hros_logo.stl" />
      </geometry>
      <material name="Gazebo/Black">
        <color rgba="0. 0. 0. 1" />
      </material>
    </visual>
    <collision>
      <origin xyz="0 0 0" rpy="0 0 0" />
      <geometry>
        <mesh scale="0.001 0.001 0.001" filename="package://scara_e1_description/meshes/scara_e1_hros_logo.stl" />
      </geometry>
    </collision>
  </link>


  <link name="4_dof_scara_e1_base_motor">
    <inertial>
      <origin xyz="8.625E-08 -4.6583E-06 0.03145" rpy="0 0 0" />
      <mass value="0.22652" />
      <inertia ixx="0.00020005" ixy="-4.2442E-10" ixz="-2.9069E-10" iyy="0.00017832" iyz="-3.4402E-08" izz="0.00013478" />
    </inertial>
    <visual>
      <origin xyz="0 0 0" rpy="0 0 0" />
      <geometry>
        <mesh scale="0.001 0.001 0.001" filename="package://scara_e1_description/meshes/scara_e1_base_motor.stl" />
      </geometry>
      <material name="Gazebo/Grey">
        <color rgba="0. 0. 0. 1" />
      </material>
    </visual>
    <collision>
      <origin xyz="0 0 0" rpy="0 0 0" />
      <geometry>
        <mesh scale="0.001 0.001 0.001" filename="package://scara_e1_description/meshes/scara_e1_base_motor.stl" />
      </geometry>
    </collision>
  </link>

  <link name="4_dof_scara_e1_motor1">
    <inertial>
      <origin xyz="8.625E-08 -4.6583E-06 0.03145" rpy="0 0 0" />
      <mass value="0.22652" />
      <inertia ixx="0.00020005" ixy="-4.2442E-10" ixz="-2.9069E-10" iyy="0.00017832" iyz="-3.4402E-08" izz="0.00013478" />
    </inertial>
    <visual>
      <origin xyz="0 0 0" rpy="0 0 0" />
      <geometry>
        <mesh scale="0.001 0.001 0.001" filename="package://scara_e1_description/meshes/HEBImotor_case.stl" />
      </geometry>
      <material name="Gazebo/Red">
        <color rgba="0. 0. 0. 1" />
      </material>
    </visual>
    <collision>
      <origin xyz="0 0 0" rpy="0 0 0" />
      <geometry>
        <mesh scale="0.001 0.001 0.001" filename="package://scara_e1_description/meshes/HEBImotor_case.stl" />
      </geometry>
    </collision>
  </link>

  <link name="4_dof_scara_e1_motor1_inside">
    <inertial>
      <origin xyz="8.625E-08 -4.6583E-06 0.03145" rpy="0 0 0" />
      <mass value="0.22652" />
      <inertia ixx="0.00020005" ixy="-4.2442E-10" ixz="-2.9069E-10" iyy="0.00017832" iyz="-3.4402E-08" izz="0.00013478" />
    </inertial>
    <visual>
      <origin xyz="0 0 0" rpy="0 0 0" />
      <geometry>
        <mesh scale="0.001 0.001 0.001" filename="package://scara_e1_description/meshes/HEBImotor.stl" />
      </geometry>
      <material name="Gazebo/Red">
        <color rgba="0. 0. 0. 1" />
      </material>
    </visual>
    <collision>
      <origin xyz="0 0 0" rpy="0 0 0" />
      <geometry>
        <mesh scale="0.001 0.001 0.001" filename="package://scara_e1_description/meshes/HEBImotor.stl" />
      </geometry>
    </collision>
  </link>

  <link name="4_dof_scara_e1_motor1_support">
    <inertial>
      <origin xyz="8.625E-08 -4.6583E-06 0.03145" rpy="0 0 0" />
      <mass value="0.22652" />
      <inertia ixx="0.00020005" ixy="-4.2442E-10" ixz="-2.9069E-10" iyy="0.00017832" iyz="-3.4402E-08" izz="0.00013478" />
    </inertial>
    <visual>
      <origin xyz="0 0 0" rpy="0 0 0" />
      <geometry>
        <mesh scale="0.001 0.001 0.001" filename="package://scara_e1_description/meshes/HEBImotor_support.stl" />
      </geometry>
      <material name="Gazebo/Grey">
        <color rgba="0. 0. 0. 1" />
      </material>
    </visual>
    <collision>
      <origin xyz="0 0 0" rpy="0 0 0" />
      <geometry>
        <mesh scale="0.001 0.001 0.001" filename="package://scara_e1_description/meshes/HEBImotor_support.stl" />
      </geometry>
    </collision>
  </link>

  <link name="4_dof_scara_e1_bar1">
    <inertial>
      <origin xyz="8.625E-08 -4.6583E-06 0.03145" rpy="0 0 0" />
      <mass value="0.22652" />
      <inertia ixx="0.00020005" ixy="-4.2442E-10" ixz="-2.9069E-10" iyy="0.00017832" iyz="-3.4402E-08" izz="0.00013478" />
    </inertial>
    <visual>
      <origin xyz="0 0 0" rpy="0 0 0" />
      <geometry>
        <mesh scale="0.001 0.001 0.001" filename="package://scara_e1_description/meshes/scara_bar.stl" />
      </geometry>
      <material name="Gazebo/White">
        <color rgba="0. 0. 0. 1" />
      </material>
    </visual>
    <collision>
      <origin xyz="0 0 0" rpy="0 0 0" />
      <geometry>
        <mesh scale="0.001 0.001 0.001" filename="package://scara_e1_description/meshes/scara_bar.stl" />
      </geometry>
    </collision>
  </link>

  <link name="4_dof_scara_e1_fixbar1">
    <inertial>
      <origin xyz="8.625E-08 -4.6583E-06 0.03145" rpy="0 0 0" />
      <mass value="0.22652" />
      <inertia ixx="0.00020005" ixy="-4.2442E-10" ixz="-2.9069E-10" iyy="0.00017832" iyz="-3.4402E-08" izz="0.00013478" />
    </inertial>
    <visual>
      <origin xyz="0 0 0" rpy="0 0 0" />
      <geometry>
        <mesh scale="0.001 0.001 0.001" filename="package://scara_e1_description/meshes/HEBImotor_fixbar.stl" />
      </geometry>
      <material name="Gazebo/Grey">
        <color rgba="0. 0. 0. 1" />
      </material>
    </visual>
    <collision>
      <origin xyz="0 0 0" rpy="0 0 0" />
      <geometry>
        <mesh scale="0.001 0.001 0.001" filename="package://scara_e1_description/meshes/HEBImotor_fixbar.stl" />
      </geometry>
    </collision>
  </link>

  <link name="4_dof_scara_e1_motor2">
    <inertial>
      <origin xyz="8.625E-08 -4.6583E-06 0.03145" rpy="0 0 0" />
      <mass value="0.22652" />
      <inertia ixx="0.00020005" ixy="-4.2442E-10" ixz="-2.9069E-10" iyy="0.00017832" iyz="-3.4402E-08" izz="0.00013478" />
    </inertial>
    <visual>
      <origin xyz="0 0 0" rpy="0 0 0" />
      <geometry>
        <mesh scale="0.001 0.001 0.001" filename="package://scara_e1_description/meshes/HEBImotor_case.stl" />
      </geometry>
      <material name="Gazebo/Red">
        <color rgba="0. 0. 0. 1" />
      </material>
    </visual>
    <collision>
      <origin xyz="0 0 0" rpy="0 0 0" />
      <geometry>
        <mesh scale="0.001 0.001 0.001" filename="package://scara_e1_description/meshes/HEBImotor_case.stl" />
      </geometry>
    </collision>
  </link>

  <link name="4_dof_scara_e1_motor2_inside">
    <inertial>
      <origin xyz="8.625E-08 -4.6583E-06 0.03145" rpy="0 0 0" />
      <mass value="0.22652" />
      <inertia ixx="0.00020005" ixy="-4.2442E-10" ixz="-2.9069E-10" iyy="0.00017832" iyz="-3.4402E-08" izz="0.00013478" />
    </inertial>
    <visual>
      <origin xyz="0 0 0" rpy="0 0 0" />
      <geometry>
        <mesh scale="0.001 0.001 0.001" filename="package://scara_e1_description/meshes/HEBImotor.stl" />
      </geometry>
      <material name="Gazebo/Red">
        <color rgba="0. 0. 0. 1" />
      </material>
    </visual>
    <collision>
      <origin xyz="0 0 0" rpy="0 0 0" />
      <geometry>
        <mesh scale="0.001 0.001 0.001" filename="package://scara_e1_description/meshes/HEBImotor.stl" />
      </geometry>
    </collision>
  </link>

  <link name="4_dof_scara_e1_motor2_support">
    <inertial>
      <origin xyz="8.625E-08 -4.6583E-06 0.03145" rpy="0 0 0" />
      <mass value="0.22652" />
      <inertia ixx="0.00020005" ixy="-4.2442E-10" ixz="-2.9069E-10" iyy="0.00017832" iyz="-3.4402E-08" izz="0.00013478" />
    </inertial>
    <visual>
      <origin xyz="0 0 0" rpy="0 0 0" />
      <geometry>
        <mesh scale="0.001 0.001 0.001" filename="package://scara_e1_description/meshes/HEBImotor_support.stl" />
      </geometry>
      <material name="Gazebo/Grey">
        <color rgba="0. 0. 0. 1" />
      </material>
    </visual>
    <collision>
      <origin xyz="0 0 0" rpy="0 0 0" />
      <geometry>
        <mesh scale="0.001 0.001 0.001" filename="package://scara_e1_description/meshes/HEBImotor_support.stl" />
      </geometry>
    </collision>
  </link>

  <link name="4_dof_scara_e1_bar2">
    <inertial>
      <origin xyz="8.625E-08 -4.6583E-06 0.03145" rpy="0 0 0" />
      <mass value="0.22652" />
      <inertia ixx="0.00020005" ixy="-4.2442E-10" ixz="-2.9069E-10" iyy="0.00017832" iyz="-3.4402E-08" izz="0.00013478" />
    </inertial>
    <visual>
      <origin xyz="0 0 0" rpy="0 0 0" />
      <geometry>
        <mesh scale="0.001 0.001 0.001" filename="package://scara_e1_description/meshes/scara_bar.stl" />
      </geometry>
      <material name="Gazebo/White">
        <color rgba="0. 0. 0. 1" />
      </material>
    </visual>
    <collision>
      <origin xyz="0 0 0" rpy="0 0 0" />
      <geometry>
        <mesh scale="0.001 0.001 0.001" filename="package://scara_e1_description/meshes/scara_bar.stl" />
      </geometry>
    </collision>
  </link>

  <link name="4_dof_scara_e1_fixbar2">
    <inertial>
      <origin xyz="8.625E-08 -4.6583E-06 0.03145" rpy="0 0 0" />
      <mass value="0.22652" />
      <inertia ixx="0.00020005" ixy="-4.2442E-10" ixz="-2.9069E-10" iyy="0.00017832" iyz="-3.4402E-08" izz="0.00013478" />
    </inertial>
    <visual>
      <origin xyz="0 0 0" rpy="0 0 0" />
      <geometry>
        <mesh scale="0.001 0.001 0.001" filename="package://scara_e1_description/meshes/HEBImotor_fixbar.stl" />
      </geometry>
      <material name="Gazebo/Grey">
        <color rgba="0. 0. 0. 1" />
      </material>
    </visual>
    <collision>
      <origin xyz="0 0 0" rpy="0 0 0" />
      <geometry>
        <mesh scale="0.001 0.001 0.001" filename="package://scara_e1_description/meshes/HEBImotor_fixbar.stl" />
      </geometry>
    </collision>
  </link>

  <link name="4_dof_scara_e1_motor3">
    <inertial>
      <origin xyz="8.625E-08 -4.6583E-06 0.03145" rpy="0 0 0" />
      <mass value="0.22652" />
      <inertia ixx="0.00020005" ixy="-4.2442E-10" ixz="-2.9069E-10" iyy="0.00017832" iyz="-3.4402E-08" izz="0.00013478" />
    </inertial>
    <visual>
      <origin xyz="0 0 0" rpy="0 0 0" />
      <geometry>
        <mesh scale="0.001 0.001 0.001" filename="package://scara_e1_description/meshes/HEBImotor_case.stl" />
      </geometry>
      <material name="Gazebo/Red">
        <color rgba="0. 0. 0. 1" />
      </material>
    </visual>
    <collision>
      <origin xyz="0 0 0" rpy="0 0 0" />
      <geometry>
        <mesh scale="0.001 0.001 0.001" filename="package://scara_e1_description/meshes/HEBImotor_case.stl" />
      </geometry>
    </collision>
  </link>

  <link name="4_dof_scara_e1_motor3_inside">
    <inertial>
      <origin xyz="8.625E-08 -4.6583E-06 0.03145" rpy="0 0 0" />
      <mass value="0.22652" />
      <inertia ixx="0.00020005" ixy="-4.2442E-10" ixz="-2.9069E-10" iyy="0.00017832" iyz="-3.4402E-08" izz="0.00013478" />
    </inertial>
    <visual>
      <origin xyz="0 0 0" rpy="0 0 0" />
      <geometry>
        <mesh scale="0.001 0.001 0.001" filename="package://scara_e1_description/meshes/HEBImotor.stl" />
      </geometry>
      <material name="Gazebo/Red">
        <color rgba="0. 0. 0. 1" />
      </material>
    </visual>
    <collision>
      <origin xyz="0 0 0" rpy="0 0 0" />
      <geometry>
        <mesh scale="0.001 0.001 0.001" filename="package://scara_e1_description/meshes/HEBImotor.stl" />
      </geometry>
    </collision>
  </link>

  <link name="4_dof_scara_e1_motor3_support">
    <inertial>
      <origin xyz="8.625E-08 -4.6583E-06 0.03145" rpy="0 0 0" />
      <mass value="0.22652" />
      <inertia ixx="0.00020005" ixy="-4.2442E-10" ixz="-2.9069E-10" iyy="0.00017832" iyz="-3.4402E-08" izz="0.00013478" />
    </inertial>
    <visual>
      <origin xyz="0 0 0" rpy="0 0 0" />
      <geometry>
        <mesh scale="0.001 0.001 0.001" filename="package://scara_e1_description/meshes/HEBImotor_support.stl" />
      </geometry>
      <material name="Gazebo/Grey">
        <color rgba="0. 0. 0. 1" />
      </material>
    </visual>
    <collision>
      <origin xyz="0 0 0" rpy="0 0 0" />
      <geometry>
        <mesh scale="0.001 0.001 0.001" filename="package://scara_e1_description/meshes/HEBImotor_support.stl" />
      </geometry>
    </collision>
  </link>

  <link name="4_dof_scara_e1_bar3">
    <inertial>
      <origin xyz="8.625E-08 -4.6583E-06 0.03145" rpy="0 0 0" />
      <mass value="0.22652" />
      <inertia ixx="0.00020005" ixy="-4.2442E-10" ixz="-2.9069E-10" iyy="0.00017832" iyz="-3.4402E-08" izz="0.00013478" />
    </inertial>
    <visual>
      <origin xyz="0 0 0" rpy="0 0 0" />
      <geometry>
        <mesh scale="0.001 0.001 0.001" filename="package://scara_e1_description/meshes/scara_bar.stl" />
      </geometry>
      <material name="Gazebo/White">
        <color rgba="0. 0. 0. 1" />
      </material>
    </visual>
    <collision>
      <origin xyz="0 0 0" rpy="0 0 0" />
      <geometry>
        <mesh scale="0.001 0.001 0.001" filename="package://scara_e1_description/meshes/scara_bar.stl" />
      </geometry>
    </collision>
  </link>

  <link name="4_dof_scara_e1_fixbar3">
    <inertial>
      <origin xyz="8.625E-08 -4.6583E-06 0.03145" rpy="0 0 0" />
      <mass value="0.22652" />
      <inertia ixx="0.00020005" ixy="-4.2442E-10" ixz="-2.9069E-10" iyy="0.00017832" iyz="-3.4402E-08" izz="0.00013478" />
    </inertial>
    <visual>
      <origin xyz="0 0 0" rpy="0 0 0" />
      <geometry>
        <mesh scale="0.001 0.001 0.001" filename="package://scara_e1_description/meshes/HEBImotor_fixbar.stl" />
      </geometry>
      <material name="Gazebo/Grey">
        <color rgba="0. 0. 0. 1" />
      </material>
    </visual>
    <collision>
      <origin xyz="0 0 0" rpy="0 0 0" />
      <geometry>
        <mesh scale="0.001 0.001 0.001" filename="package://scara_e1_description/meshes/HEBImotor_fixbar.stl" />
      </geometry>
    </collision>
  </link>

  <link name="4_dof_scara_e1_motor4">
    <inertial>
      <origin xyz="8.625E-08 -4.6583E-06 0.03145" rpy="0 0 0" />
      <mass value="0.22652" />
      <inertia ixx="0.00020005" ixy="-4.2442E-10" ixz="-2.9069E-10" iyy="0.00017832" iyz="-3.4402E-08" izz="0.00013478" />
    </inertial>
    <visual>
      <origin xyz="0 0 0" rpy="0 0 0" />
      <geometry>
        <mesh scale="0.001 0.001 0.001" filename="package://scara_e1_description/meshes/HEBImotor_case.stl" />
      </geometry>
      <material name="Gazebo/Red">
        <color rgba="0. 0. 0. 1" />
      </material>
    </visual>
    <collision>
      <origin xyz="0 0 0" rpy="0 0 0" />
      <geometry>
        <mesh scale="0.001 0.001 0.001" filename="package://scara_e1_description/meshes/HEBImotor_case.stl" />
      </geometry>
    </collision>
  </link>

  <link name="4_dof_scara_e1_motor4_inside">
    <inertial>
      <origin xyz="8.625E-08 -4.6583E-06 0.03145" rpy="0 0 0" />
      <mass value="0.22652" />
      <inertia ixx="0.00020005" ixy="-4.2442E-10" ixz="-2.9069E-10" iyy="0.00017832" iyz="-3.4402E-08" izz="0.00013478" />
    </inertial>
    <visual>
      <origin xyz="0 0 0" rpy="0 0 0" />
      <geometry>
        <mesh scale="0.001 0.001 0.001" filename="package://scara_e1_description/meshes/HEBImotor.stl" />
      </geometry>
      <material name="Gazebo/Red">
        <color rgba="0. 0. 0. 1" />
      </material>
    </visual>
    <collision>
      <origin xyz="0 0 0" rpy="0 0 0" />
      <geometry>
        <mesh scale="0.001 0.001 0.001" filename="package://scara_e1_description/meshes/HEBImotor.stl" />
      </geometry>
    </collision>
  </link>

  <link name="4_dof_scara_e1_motor4_support">
    <inertial>
      <origin xyz="8.625E-08 -4.6583E-06 0.03145" rpy="0 0 0" />
      <mass value="0.22652" />
      <inertia ixx="0.00020005" ixy="-4.2442E-10" ixz="-2.9069E-10" iyy="0.00017832" iyz="-3.4402E-08" izz="0.00013478" />
    </inertial>
    <visual>
      <origin xyz="0 0 0" rpy="0 0 0" />
      <geometry>
        <mesh scale="0.001 0.001 0.001" filename="package://scara_e1_description/meshes/HEBImotor_support.stl" />
      </geometry>
      <material name="Gazebo/Grey">
        <color rgba="0. 0. 0. 1" />
      </material>
    </visual>
    <collision>
      <origin xyz="0 0 0" rpy="0 0 0" />
      <geometry>
        <mesh scale="0.001 0.001 0.001" filename="package://scara_e1_description/meshes/HEBImotor_support.stl" />
      </geometry>
    </collision>
  </link>

  <link name="4_dof_scara_e1_bar4">
    <inertial>
      <origin xyz="8.625E-08 -4.6583E-06 0.03145" rpy="0 0 0" />
      <mass value="0.22652" />
      <inertia ixx="0.00020005" ixy="-4.2442E-10" ixz="-2.9069E-10" iyy="0.00017832" iyz="-3.4402E-08" izz="0.00013478" />
    </inertial>
    <visual>
      <origin xyz="0 0 0" rpy="0 0 0" />
      <geometry>
        <mesh scale="0.001 0.001 0.001" filename="package://scara_e1_description/meshes/scara_bar.stl" />
      </geometry>
      <material name="Gazebo/White">
        <color rgba="0. 0. 0. 1" />
      </material>
    </visual>
    <collision>
      <origin xyz="0 0 0" rpy="0 0 0" />
      <geometry>
        <mesh scale="0.001 0.001 0.001" filename="package://scara_e1_description/meshes/scara_bar.stl" />
      </geometry>
    </collision>
  </link>

  <link name="4_dof_scara_e1_rangefinder">
    <inertial>
      <origin xyz="8.625E-08 -4.6583E-06 0.03145" rpy="0 0 0" />
      <mass value="0.22652" />
      <inertia ixx="0.00020005" ixy="-4.2442E-10" ixz="-2.9069E-10" iyy="0.00017832" iyz="-3.4402E-08" izz="0.00013478" />
    </inertial>
    <visual>
      <origin xyz="0 0 0" rpy="0 0 0" />
      <geometry>
        <mesh scale="0.001 0.001 0.001" filename="package://scara_e1_description/meshes/scara_e1_rangefinder.stl" />
      </geometry>
      <material name="Gazebo/Blue">
        <color rgba="0. 0. 0. 1" />
      </material>
    </visual>
    <collision>
      <origin xyz="0 0 0" rpy="0 0 0" />
      <geometry>
        <mesh scale="0.001 0.001 0.001" filename="package://scara_e1_description/meshes/scara_e1_rangefinder.stl" />
      </geometry>
    </collision>
  </link>

  <link name="4_dof_ee_link"/>

  <joint name="4_dof_world_to_base_joint" type="fixed">
    <origin xyz="0.7 0 0" rpy="0 0 -1.57"/>
    <parent link="world"/>
    <child link="4_dof_scara_e1_base_link"/>
  </joint>

  <joint name="4_dof_logo_joint" type="fixed">
    <origin xyz="0.7 ${-0.332} 0.045" rpy="0 0 -1.57"/>
    <parent link="world"/>
    <child link="4_dof_scara_e1_hros_logo"/>
  </joint>

  <joint name="4_dof_base_to_metraquilato_joint" type="fixed">
    <origin xyz="0.7 0 0" rpy="0 0 -1.57"/>
    <parent link="world"/>
    <child link="4_dof_scara_e1_metraquilato"/>
  </joint>


  <joint name="4_dof_base_to_base_motor_joint" type="fixed">
  <origin xyz="-0.285 0 0.08" rpy="0 0 1.57"/>
    <parent link="4_dof_scara_e1_base_link"/>
    <child link="4_dof_scara_e1_base_motor"/>
  </joint>

  <joint name="4_dof_base_to_motor1_joint" type="fixed">
    <origin xyz="0 0. 0" rpy="0 0 0"/>
    <parent link="4_dof_scara_e1_base_motor"/>
    <child link="4_dof_scara_e1_motor1"/>
  </joint>

  <joint name="4_dof_base_to_motor1_inside_joint" type="fixed">
    <origin xyz="0 0. 0" rpy="0 0 0"/>
    <parent link="4_dof_scara_e1_motor1"/>
    <child link="4_dof_scara_e1_motor1_inside"/>
  </joint>

  <joint name="motor1_4dof" type="revolute">
    <origin xyz="-0.0313 0 0.0702" rpy="0 0 1.57" />
    <parent link="4_dof_scara_e1_motor1_inside" />
    <child link="4_dof_scara_e1_motor1_support" />
    <axis xyz="0 0 1" />
    <limit lower="-3.14" upper="3.14"  velocity="10.0" effort="10" />
    <dynamics damping="0" friction="0"/>
  </joint>

  <joint name="4_dof_base_to_bar1_joint" type="fixed">
    <origin xyz="-0.1155 0. 0.0240" rpy="0 0 0"/>
    <parent link="4_dof_scara_e1_motor1_support"/>
    <child link="4_dof_scara_e1_bar1"/>
  </joint>

  <joint name="4_dof_scara_e1_fixbar1_joint" type="fixed">
    <origin xyz="-0.0783 0. 0.0180" rpy="0 0 3.14"/>
    <parent link="4_dof_scara_e1_bar1"/>
    <child link="4_dof_scara_e1_fixbar1"/>
  </joint>

  <joint name="4_dof_base_to_motor2_joint" type="fixed">
    <origin xyz="0 0. 0" rpy="0 0 3.1416"/>
    <parent link="4_dof_scara_e1_fixbar1"/>
    <child link="4_dof_scara_e1_motor2"/>
  </joint>

  <joint name="4_dof_base_to_motor2_inside_joint" type="fixed">
    <origin xyz="0 0. 0" rpy="0 0 0"/>
    <parent link="4_dof_scara_e1_motor2"/>
    <child link="4_dof_scara_e1_motor2_inside"/>
  </joint>

  <joint name="motor2_4dof" type="revolute">
    <origin xyz="-0.0313 0 0.0702" rpy="0 0 0" />
    <parent link="4_dof_scara_e1_motor2_inside" />
    <child link="4_dof_scara_e1_motor2_support" />
    <axis xyz="0 0 1" />
    <limit lower="-3.14" upper="3.14"  velocity="10.0" effort="10" />
    <dynamics damping="0" friction="0"/>
  </joint>

  <joint name="4_dof_base_to_bar2_joint" type="fixed">
    <origin xyz="-0.1155 0. 0.0240" rpy="0 0 0"/>
    <parent link="4_dof_scara_e1_motor2_support"/>
    <child link="4_dof_scara_e1_bar2"/>
  </joint>

  <joint name="4_dof_scara_e1_fixbar2_joint" type="fixed">
    <origin xyz="-0.0783 0. 0.0180" rpy="0 0 3.14"/>
    <parent link="4_dof_scara_e1_bar2"/>
    <child link="4_dof_scara_e1_fixbar2"/>
  </joint>

  <joint name="4_dof_base_to_motor3_joint" type="fixed">
    <origin xyz="0 0. 0" rpy="0 0 3.1416"/>
    <parent link="4_dof_scara_e1_fixbar2"/>
    <child link="4_dof_scara_e1_motor3"/>
  </joint>

  <joint name="4_dof_base_to_motor3_inside_joint" type="fixed">
    <origin xyz="0 0. 0" rpy="0 0 0"/>
    <parent link="4_dof_scara_e1_motor3"/>
    <child link="4_dof_scara_e1_motor3_inside"/>
  </joint>

  <joint name="motor3_4dof" type="revolute">
    <origin xyz="-0.0313 0 0.0702" rpy="0 0 0" />
    <parent link="4_dof_scara_e1_motor3_inside" />
    <child link="4_dof_scara_e1_motor3_support" />
    <axis xyz="0 0 1" />
    <limit lower="-3.14" upper="3.14"  velocity="10.0" effort="10" />
    <dynamics damping="0" friction="0"/>
  </joint>

  <joint name="4_dof_base_to_bar3_joint" type="fixed">
    <origin xyz="-0.1155 0. 0.0240" rpy="0 0 0"/>
    <parent link="4_dof_scara_e1_motor3_support"/>
    <child link="4_dof_scara_e1_bar3"/>
  </joint>

  <joint name="4_dof_scara_e1_fixbar3_joint" type="fixed">
    <origin xyz="-0.0783 0. 0.0180" rpy="0 0 3.14"/>
    <parent link="4_dof_scara_e1_bar3"/>
    <child link="4_dof_scara_e1_fixbar3"/>
  </joint>

  <joint name="4_dof_base_to_motor4_joint" type="fixed">
    <origin xyz="0 0. 0" rpy="0 0 3.1416"/>
    <parent link="4_dof_scara_e1_fixbar3"/>
    <child link="4_dof_scara_e1_motor4"/>
  </joint>

  <joint name="4_dof_base_to_motor4_inside_joint" type="fixed">
    <origin xyz="0 0. 0" rpy="0 0 0"/>
    <parent link="4_dof_scara_e1_motor4"/>
    <child link="4_dof_scara_e1_motor4_inside"/>
  </joint>

  <joint name="motor4_4dof" type="revolute">
    <origin xyz="-0.0313 0 0.0702" rpy="0 0 0" />
    <parent link="4_dof_scara_e1_motor4_inside" />
    <child link="4_dof_scara_e1_motor4_support" />
    <axis xyz="0 0 1" />
    <limit lower="-3.14" upper="3.14"  velocity="10.0" effort="10" />
    <dynamics damping="0" friction="0"/>
  </joint>

  <joint name="4_dof_base_to_bar4_joint" type="fixed">
    <origin xyz="-0.1155 0. 0.0240" rpy="0 0 0"/>
    <parent link="4_dof_scara_e1_motor4_support"/>
    <child link="4_dof_scara_e1_bar4"/>
  </joint>

  <joint name="r4_dof_angefinder_joint" type="fixed">
    <origin xyz="-0.083 0 0.037" rpy="0 0 3.1416"/>
    <parent link="4_dof_scara_e1_bar4"/>
    <child link="4_dof_scara_e1_rangefinder"/>
  </joint>

  <joint name="4_dof_ee_link_joint" type="fixed">
    <origin xyz="-0.245 0 0" rpy="0 0 0"/>
    <parent link="4_dof_scara_e1_motor4_support"/>
    <child link="4_dof_ee_link"/>
  </joint>

  <transmission name="motor1_trans">
    <type>transmission_interface/SimpleTransmission</type>
    <joint name="motor1_4dof">
      <hardwareInterface>PositionJointInterface</hardwareInterface>
    </joint>
    <actuator name="motor1_4dof">
      <mechanicalReduction>1</mechanicalReduction>
    </actuator>
  </transmission>

  <transmission name="moto2_trans">
    <type>transmission_interface/SimpleTransmission</type>
    <joint name="motor2_4dof">
      <hardwareInterface>PositionJointInterface</hardwareInterface>
    </joint>
    <actuator name="motor2_4dof">
      <mechanicalReduction>1</mechanicalReduction>
    </actuator>
  </transmission>

  <transmission name="motor3_trans">
    <type>transmission_interface/SimpleTransmission</type>
    <joint name="motor3_4dof">
      <hardwareInterface>PositionJointInterface</hardwareInterface>
    </joint>
    <actuator name="motor3_4dof">
      <mechanicalReduction>1</mechanicalReduction>
    </actuator>
  </transmission>

  <transmission name="motor4_trans">
    <type>transmission_interface/SimpleTransmission</type>
    <joint name="motor4_4dof">
      <hardwareInterface>PositionJointInterface</hardwareInterface>
    </joint>
    <actuator name="motor4_4dof">
      <mechanicalReduction>1</mechanicalReduction>
    </actuator>
  </transmission>


  <gazebo reference="4_dof_scara_e1_base_link">
    <material>Gazebo/Grey</material>
    <selfCollide>False</selfCollide>
  </gazebo>

  <gazebo reference="4_dof_scara_e1_base_motor">
    <material>Gazebo/Grey</material>
    <selfCollide>False</selfCollide>
  </gazebo>

  <gazebo reference="4_dof_scara_e1_metraquilato">
    <material>Gazebo/Black</material>
    <selfCollide>False</selfCollide>
  </gazebo>

  <gazebo reference="4_dof_scara_e1_hros_logo">
    <material>Gazebo/Black</material>
    <selfCollide>False</selfCollide>
  </gazebo>

  <gazebo reference="4_dof_scara_e1_motor1">
    <material>Gazebo/Black</material>
    <selfCollide>False</selfCollide>
  </gazebo>

  <gazebo reference="4_dof_scara_e1_motor1_inside">
    <material>Gazebo/Red</material>
    <selfCollide>False</selfCollide>
  </gazebo>

  <gazebo reference="4_dof_scara_e1_motor1_support">
    <material>Gazebo/Grey</material>
    <selfCollide>False</selfCollide>
  </gazebo>

  <gazebo reference="4_dof_scara_e1_bar1">
    <material>Gazebo/White</material>
    <selfCollide>False</selfCollide>
  </gazebo>

  <gazebo reference="4_dof_scara_e1_fixbar1">
    <material>Gazebo/White</material>
    <selfCollide>False</selfCollide>
  </gazebo>

  <gazebo reference="4_dof_scara_e1_motor2">
    <material>Gazebo/Black</material>
    <selfCollide>False</selfCollide>
  </gazebo>

  <gazebo reference="4_dof_scara_e1_motor2_inside">
    <material>Gazebo/Red</material>
    <selfCollide>False</selfCollide>
  </gazebo>

  <gazebo reference="4_dof_scara_e1_motor3">
    <material>Gazebo/Black</material>
    <selfCollide>False</selfCollide>
  </gazebo>

  <gazebo reference="4_dof_scara_e1_motor3_inside">
    <material>Gazebo/Red</material>
    <selfCollide>False</selfCollide>
  </gazebo>

  <gazebo reference="4_dof_scara_e1_motor3_support">
    <material>Gazebo/Grey</material>
    <selfCollide>False</selfCollide>
  </gazebo>

  <gazebo reference="4_dof_scara_e1_bar3">
    <material>Gazebo/White</material>
    <selfCollide>False</selfCollide>
  </gazebo>

  <gazebo reference="4_dof_scara_e1_fixbar3">
    <material>Gazebo/White</material>
    <selfCollide>False</selfCollide>
  </gazebo>

  <gazebo reference="4_dof_scara_e1_motor4">
    <material>Gazebo/Black</material>
    <selfCollide>False</selfCollide>
  </gazebo>

  <gazebo reference="4_dof_scara_e1_motor4_inside">
    <material>Gazebo/Red</material>
    <selfCollide>False</selfCollide>
  </gazebo>

  <gazebo reference="4_dof_scara_e1_bar4">
    <material>Gazebo/White</material>
    <selfCollide>False</selfCollide>
  </gazebo>

  <gazebo reference="4_dof_scara_e1_rangefinder">
    <material>Gazebo/Blue</material>
    <selfCollide>False</selfCollide>
  </gazebo>

  <gazebo>
     <plugin name="gazebo_ros_control" filename="libgazebo_ros_control.so">
       <robotNamespace>/</robotNamespace>
       <robotSimType>gazebo_ros_control/DefaultRobotHWSim</robotSimType>
     </plugin>
  </gazebo>

  <gazebo reference="ee_link">
    <sensor type ="ray" name="scara_e1_rangefinder_sensor">
      <visualize>true</visualize>
      <update_rate>20</update_rate>
      <ray>
        <scan>
          <horizontal>
            <samples>1</samples>
            <resolution>1</resolution>
            <min_angle>-0.17</min_angle>
            <max_angle>0.17</max_angle>
          </horizontal>
          <vertical>
            <samples>40</samples>
            <resolution>1</resolution>
            <min_angle>-1.574</min_angle>
            <max_angle>-1.572</max_angle>
          </vertical>
        </scan>
        <range>
          <min>0</min>
          <max>2</max>
          <resolution>0.01</resolution>
        </range>
      </ray>
      <plugin name="laser" filename="libgazebo_ros_laser.so">
        <topicName>/scan</topicName>
        <frameName>ee_link</frameName>
      </plugin>
    </sensor>
</gazebo>

  <gazebo reference="4_dof_ee_link">
    <sensor type ="ray" name="scara_e1_rangefinder_sensor_4_dof">
      <visualize>true</visualize>
      <update_rate>20</update_rate>
      <ray>
        <scan>
          <horizontal>
            <samples>1</samples>
            <resolution>1</resolution>
            <min_angle>-0.17</min_angle>
            <max_angle>0.17</max_angle>
          </horizontal>
          <vertical>
            <samples>40</samples>
            <resolution>1</resolution>
            <min_angle>-1.574</min_angle>
            <max_angle>-1.572</max_angle>
          </vertical>
        </scan>
        <range>
          <min>0</min>
          <max>2</max>
          <resolution>0.01</resolution>
        </range>
      </ray>
      <plugin name="laser" filename="libgazebo_ros_laser.so">
        <topicName>/scan_4dof</topicName>
        <frameName>4_dof_ee_link</frameName>
      </plugin>
    </sensor>
  </gazebo>

</robot>
