<?xml version="1.0" ?>
<!-- =================================================================================== -->
<!-- |    This document was autogenerated by xacro from scara_e1_model_4joints.urdf.xacro | -->
<!-- |    EDITING THIS FILE BY HAND IS NOT RECOMMENDED                                 | -->
<!-- =================================================================================== -->
<robot name="scara_e1_4joints" xmlns:xacro="http://ros.org/wiki/xacro">
  <link name="world">
    <visual>
      <geometry>
        <box size="1.5 0.8 0.001"/>
      </geometry>
      <origin rpy="0 0 0" xyz="0 0 0"/>
      <material name="Gazebo/Black">
       </material>
    </visual>
  </link>
  <link name="scara_e1_base_link">
    <inertial>
      <origin rpy="0 0 0" xyz="8.625E-08 -4.6583E-06 0.03145"/>
      <mass value="0.22652"/>
      <inertia ixx="0.00020005" ixy="-4.2442E-10" ixz="-2.9069E-10" iyy="0.00017832" iyz="-3.4402E-08" izz="0.00013478"/>
    </inertial>
    <visual>
      <origin rpy="0 0 0" xyz="0 0 0"/>
      <geometry>
        <mesh filename="package://scara_e1_description/meshes/scara_e1_base_link.stl" scale="0.001 0.001 0.001"/>
      </geometry>
      <material name="Gazebo/Grey">
        <color rgba="0. 0. 0. 1"/>
      </material>
    </visual>
    <collision>
      <origin rpy="0 0 0" xyz="0 0 0"/>
      <geometry>
        <mesh filename="package://scara_e1_description/meshes/scara_e1_base_link.stl" scale="0.001 0.001 0.001"/>
      </geometry>
    </collision>
  </link>
  <link name="scara_e1_metraquilato">
    <inertial>
      <origin rpy="0 0 0" xyz="8.625E-08 -4.6583E-06 0.03145"/>
      <mass value="0.22652"/>
      <inertia ixx="0.00020005" ixy="-4.2442E-10" ixz="-2.9069E-10" iyy="0.00017832" iyz="-3.4402E-08" izz="0.00013478"/>
    </inertial>
    <visual>
      <origin rpy="0 0 0" xyz="0 0 0"/>
      <geometry>
        <mesh filename="package://scara_e1_description/meshes/scara_e1_metacrilato.stl" scale="0.001 0.001 0.001"/>
      </geometry>
      <material name="Gazebo/Black">
        <color rgba="0. 0. 0. 1"/>
      </material>
    </visual>
    <collision>
      <origin rpy="0 0 0" xyz="0 0 0"/>
      <geometry>
        <mesh filename="package://scara_e1_description/meshes/scara_e1_metacrilato.stl" scale="0.001 0.001 0.001"/>
      </geometry>
    </collision>
  </link>
  <link name="scara_e1_hros_logo">
    <inertial>
      <origin rpy="0 0 0" xyz="8.625E-08 -4.6583E-06 0.03145"/>
      <mass value="0.22652"/>
      <inertia ixx="0.00020005" ixy="-4.2442E-10" ixz="-2.9069E-10" iyy="0.00017832" iyz="-3.4402E-08" izz="0.00013478"/>
    </inertial>
    <visual>
      <origin rpy="0 0 0" xyz="0 0 0"/>
      <geometry>
        <mesh filename="package://scara_e1_description/meshes/scara_e1_hros_logo.stl" scale="0.001 0.001 0.001"/>
      </geometry>
      <material name="Gazebo/Black">
        <color rgba="0. 0. 0. 1"/>
      </material>
    </visual>
    <collision>
      <origin rpy="0 0 0" xyz="0 0 0"/>
      <geometry>
        <mesh filename="package://scara_e1_description/meshes/scara_e1_hros_logo.stl" scale="0.001 0.001 0.001"/>
      </geometry>
    </collision>
  </link>
  <link name="scara_e1_base_motor">
    <inertial>
      <origin rpy="0 0 0" xyz="8.625E-08 -4.6583E-06 0.03145"/>
      <mass value="0.22652"/>
      <inertia ixx="0.00020005" ixy="-4.2442E-10" ixz="-2.9069E-10" iyy="0.00017832" iyz="-3.4402E-08" izz="0.00013478"/>
    </inertial>
    <visual>
      <origin rpy="0 0 0" xyz="0 0 0"/>
      <geometry>
        <mesh filename="package://scara_e1_description/meshes/scara_e1_base_motor.stl" scale="0.001 0.001 0.001"/>
      </geometry>
      <material name="Gazebo/Grey">
        <color rgba="0. 0. 0. 1"/>
      </material>
    </visual>
    <collision>
      <origin rpy="0 0 0" xyz="0 0 0"/>
      <geometry>
        <mesh filename="package://scara_e1_description/meshes/scara_e1_base_motor.stl" scale="0.001 0.001 0.001"/>
      </geometry>
    </collision>
  </link>
  <link name="scara_e1_motor1">
    <inertial>
      <origin rpy="0 0 0" xyz="8.625E-08 -4.6583E-06 0.03145"/>
      <mass value="0.22652"/>
      <inertia ixx="0.00020005" ixy="-4.2442E-10" ixz="-2.9069E-10" iyy="0.00017832" iyz="-3.4402E-08" izz="0.00013478"/>
    </inertial>
    <visual>
      <origin rpy="0 0 0" xyz="0 0 0"/>
      <geometry>
        <mesh filename="package://scara_e1_description/meshes/HEBImotor_case.stl" scale="0.001 0.001 0.001"/>
      </geometry>
      <material name="Gazebo/Red">
        <color rgba="0. 0. 0. 1"/>
      </material>
    </visual>
    <collision>
      <origin rpy="0 0 0" xyz="0 0 0"/>
      <geometry>
        <mesh filename="package://scara_e1_description/meshes/HEBImotor_case.stl" scale="0.001 0.001 0.001"/>
      </geometry>
    </collision>
  </link>
  <link name="scara_e1_motor1_inside">
    <inertial>
      <origin rpy="0 0 0" xyz="8.625E-08 -4.6583E-06 0.03145"/>
      <mass value="0.22652"/>
      <inertia ixx="0.00020005" ixy="-4.2442E-10" ixz="-2.9069E-10" iyy="0.00017832" iyz="-3.4402E-08" izz="0.00013478"/>
    </inertial>
    <visual>
      <origin rpy="0 0 0" xyz="0 0 0"/>
      <geometry>
        <mesh filename="package://scara_e1_description/meshes/HEBImotor.stl" scale="0.001 0.001 0.001"/>
      </geometry>
      <material name="Gazebo/Red">
        <color rgba="0. 0. 0. 1"/>
      </material>
    </visual>
    <collision>
      <origin rpy="0 0 0" xyz="0 0 0"/>
      <geometry>
        <mesh filename="package://scara_e1_description/meshes/HEBImotor.stl" scale="0.001 0.001 0.001"/>
      </geometry>
    </collision>
  </link>
  <link name="scara_e1_motor1_support">
    <inertial>
      <origin rpy="0 0 0" xyz="8.625E-08 -4.6583E-06 0.03145"/>
      <mass value="0.22652"/>
      <inertia ixx="0.00020005" ixy="-4.2442E-10" ixz="-2.9069E-10" iyy="0.00017832" iyz="-3.4402E-08" izz="0.00013478"/>
    </inertial>
    <visual>
      <origin rpy="0 0 0" xyz="0 0 0"/>
      <geometry>
        <mesh filename="package://scara_e1_description/meshes/HEBImotor_support.stl" scale="0.001 0.001 0.001"/>
      </geometry>
      <material name="Gazebo/Grey">
        <color rgba="0. 0. 0. 1"/>
      </material>
    </visual>
    <collision>
      <origin rpy="0 0 0" xyz="0 0 0"/>
      <geometry>
        <mesh filename="package://scara_e1_description/meshes/HEBImotor_support.stl" scale="0.001 0.001 0.001"/>
      </geometry>
    </collision>
  </link>
  <link name="scara_e1_bar1">
    <inertial>
      <origin rpy="0 0 0" xyz="8.625E-08 -4.6583E-06 0.03145"/>
      <mass value="0.22652"/>
      <inertia ixx="0.00020005" ixy="-4.2442E-10" ixz="-2.9069E-10" iyy="0.00017832" iyz="-3.4402E-08" izz="0.00013478"/>
    </inertial>
    <visual>
      <origin rpy="0 0 0" xyz="0 0 0"/>
      <geometry>
        <mesh filename="package://scara_e1_description/meshes/scara_bar.stl" scale="0.001 0.001 0.001"/>
      </geometry>
      <material name="Gazebo/White">
        <color rgba="0. 0. 0. 1"/>
      </material>
    </visual>
    <collision>
      <origin rpy="0 0 0" xyz="0 0 0"/>
      <geometry>
        <mesh filename="package://scara_e1_description/meshes/scara_bar.stl" scale="0.001 0.001 0.001"/>
      </geometry>
    </collision>
  </link>
  <link name="scara_e1_fixbar1">
    <inertial>
      <origin rpy="0 0 0" xyz="8.625E-08 -4.6583E-06 0.03145"/>
      <mass value="0.22652"/>
      <inertia ixx="0.00020005" ixy="-4.2442E-10" ixz="-2.9069E-10" iyy="0.00017832" iyz="-3.4402E-08" izz="0.00013478"/>
    </inertial>
    <visual>
      <origin rpy="0 0 0" xyz="0 0 0"/>
      <geometry>
        <mesh filename="package://scara_e1_description/meshes/HEBImotor_fixbar.stl" scale="0.001 0.001 0.001"/>
      </geometry>
      <material name="Gazebo/Grey">
        <color rgba="0. 0. 0. 1"/>
      </material>
    </visual>
    <collision>
      <origin rpy="0 0 0" xyz="0 0 0"/>
      <geometry>
        <mesh filename="package://scara_e1_description/meshes/HEBImotor_fixbar.stl" scale="0.001 0.001 0.001"/>
      </geometry>
    </collision>
  </link>
  <link name="scara_e1_motor2">
    <inertial>
      <origin rpy="0 0 0" xyz="8.625E-08 -4.6583E-06 0.03145"/>
      <mass value="0.22652"/>
      <inertia ixx="0.00020005" ixy="-4.2442E-10" ixz="-2.9069E-10" iyy="0.00017832" iyz="-3.4402E-08" izz="0.00013478"/>
    </inertial>
    <visual>
      <origin rpy="0 0 0" xyz="0 0 0"/>
      <geometry>
        <mesh filename="package://scara_e1_description/meshes/HEBImotor_case.stl" scale="0.001 0.001 0.001"/>
      </geometry>
      <material name="Gazebo/Red">
        <color rgba="0. 0. 0. 1"/>
      </material>
    </visual>
    <collision>
      <origin rpy="0 0 0" xyz="0 0 0"/>
      <geometry>
        <mesh filename="package://scara_e1_description/meshes/HEBImotor_case.stl" scale="0.001 0.001 0.001"/>
      </geometry>
    </collision>
  </link>
  <link name="scara_e1_motor2_inside">
    <inertial>
      <origin rpy="0 0 0" xyz="8.625E-08 -4.6583E-06 0.03145"/>
      <mass value="0.22652"/>
      <inertia ixx="0.00020005" ixy="-4.2442E-10" ixz="-2.9069E-10" iyy="0.00017832" iyz="-3.4402E-08" izz="0.00013478"/>
    </inertial>
    <visual>
      <origin rpy="0 0 0" xyz="0 0 0"/>
      <geometry>
        <mesh filename="package://scara_e1_description/meshes/HEBImotor.stl" scale="0.001 0.001 0.001"/>
      </geometry>
      <material name="Gazebo/Red">
        <color rgba="0. 0. 0. 1"/>
      </material>
    </visual>
    <collision>
      <origin rpy="0 0 0" xyz="0 0 0"/>
      <geometry>
        <mesh filename="package://scara_e1_description/meshes/HEBImotor.stl" scale="0.001 0.001 0.001"/>
      </geometry>
    </collision>
  </link>
  <link name="scara_e1_motor2_support">
    <inertial>
      <origin rpy="0 0 0" xyz="8.625E-08 -4.6583E-06 0.03145"/>
      <mass value="0.22652"/>
      <inertia ixx="0.00020005" ixy="-4.2442E-10" ixz="-2.9069E-10" iyy="0.00017832" iyz="-3.4402E-08" izz="0.00013478"/>
    </inertial>
    <visual>
      <origin rpy="0 0 0" xyz="0 0 0"/>
      <geometry>
        <mesh filename="package://scara_e1_description/meshes/HEBImotor_support.stl" scale="0.001 0.001 0.001"/>
      </geometry>
      <material name="Gazebo/Grey">
        <color rgba="0. 0. 0. 1"/>
      </material>
    </visual>
    <collision>
      <origin rpy="0 0 0" xyz="0 0 0"/>
      <geometry>
        <mesh filename="package://scara_e1_description/meshes/HEBImotor_support.stl" scale="0.001 0.001 0.001"/>
      </geometry>
    </collision>
  </link>
  <link name="scara_e1_bar2">
    <inertial>
      <origin rpy="0 0 0" xyz="8.625E-08 -4.6583E-06 0.03145"/>
      <mass value="0.22652"/>
      <inertia ixx="0.00020005" ixy="-4.2442E-10" ixz="-2.9069E-10" iyy="0.00017832" iyz="-3.4402E-08" izz="0.00013478"/>
    </inertial>
    <visual>
      <origin rpy="0 0 0" xyz="0 0 0"/>
      <geometry>
        <mesh filename="package://scara_e1_description/meshes/scara_bar.stl" scale="0.001 0.001 0.001"/>
      </geometry>
      <material name="Gazebo/White">
        <color rgba="0. 0. 0. 1"/>
      </material>
    </visual>
    <collision>
      <origin rpy="0 0 0" xyz="0 0 0"/>
      <geometry>
        <mesh filename="package://scara_e1_description/meshes/scara_bar.stl" scale="0.001 0.001 0.001"/>
      </geometry>
    </collision>
  </link>
  <link name="scara_e1_fixbar2">
    <inertial>
      <origin rpy="0 0 0" xyz="8.625E-08 -4.6583E-06 0.03145"/>
      <mass value="0.22652"/>
      <inertia ixx="0.00020005" ixy="-4.2442E-10" ixz="-2.9069E-10" iyy="0.00017832" iyz="-3.4402E-08" izz="0.00013478"/>
    </inertial>
    <visual>
      <origin rpy="0 0 0" xyz="0 0 0"/>
      <geometry>
        <mesh filename="package://scara_e1_description/meshes/HEBImotor_fixbar.stl" scale="0.001 0.001 0.001"/>
      </geometry>
      <material name="Gazebo/Grey">
        <color rgba="0. 0. 0. 1"/>
      </material>
    </visual>
    <collision>
      <origin rpy="0 0 0" xyz="0 0 0"/>
      <geometry>
        <mesh filename="package://scara_e1_description/meshes/HEBImotor_fixbar.stl" scale="0.001 0.001 0.001"/>
      </geometry>
    </collision>
  </link>
  <link name="scara_e1_motor3">
    <inertial>
      <origin rpy="0 0 0" xyz="8.625E-08 -4.6583E-06 0.03145"/>
      <mass value="0.22652"/>
      <inertia ixx="0.00020005" ixy="-4.2442E-10" ixz="-2.9069E-10" iyy="0.00017832" iyz="-3.4402E-08" izz="0.00013478"/>
    </inertial>
    <visual>
      <origin rpy="0 0 0" xyz="0 0 0"/>
      <geometry>
        <mesh filename="package://scara_e1_description/meshes/HEBImotor_case.stl" scale="0.001 0.001 0.001"/>
      </geometry>
      <material name="Gazebo/Red">
        <color rgba="0. 0. 0. 1"/>
      </material>
    </visual>
    <collision>
      <origin rpy="0 0 0" xyz="0 0 0"/>
      <geometry>
        <mesh filename="package://scara_e1_description/meshes/HEBImotor_case.stl" scale="0.001 0.001 0.001"/>
      </geometry>
    </collision>
  </link>
  <link name="scara_e1_motor3_inside">
    <inertial>
      <origin rpy="0 0 0" xyz="8.625E-08 -4.6583E-06 0.03145"/>
      <mass value="0.22652"/>
      <inertia ixx="0.00020005" ixy="-4.2442E-10" ixz="-2.9069E-10" iyy="0.00017832" iyz="-3.4402E-08" izz="0.00013478"/>
    </inertial>
    <visual>
      <origin rpy="0 0 0" xyz="0 0 0"/>
      <geometry>
        <mesh filename="package://scara_e1_description/meshes/HEBImotor.stl" scale="0.001 0.001 0.001"/>
      </geometry>
      <material name="Gazebo/Red">
        <color rgba="0. 0. 0. 1"/>
      </material>
    </visual>
    <collision>
      <origin rpy="0 0 0" xyz="0 0 0"/>
      <geometry>
        <mesh filename="package://scara_e1_description/meshes/HEBImotor.stl" scale="0.001 0.001 0.001"/>
      </geometry>
    </collision>
  </link>
  <link name="scara_e1_motor3_support">
    <inertial>
      <origin rpy="0 0 0" xyz="8.625E-08 -4.6583E-06 0.03145"/>
      <mass value="0.22652"/>
      <inertia ixx="0.00020005" ixy="-4.2442E-10" ixz="-2.9069E-10" iyy="0.00017832" iyz="-3.4402E-08" izz="0.00013478"/>
    </inertial>
    <visual>
      <origin rpy="0 0 0" xyz="0 0 0"/>
      <geometry>
        <mesh filename="package://scara_e1_description/meshes/HEBImotor_support.stl" scale="0.001 0.001 0.001"/>
      </geometry>
      <material name="Gazebo/Grey">
        <color rgba="0. 0. 0. 1"/>
      </material>
    </visual>
    <collision>
      <origin rpy="0 0 0" xyz="0 0 0"/>
      <geometry>
        <mesh filename="package://scara_e1_description/meshes/HEBImotor_support.stl" scale="0.001 0.001 0.001"/>
      </geometry>
    </collision>
  </link>
  <link name="scara_e1_bar3">
    <inertial>
      <origin rpy="0 0 0" xyz="8.625E-08 -4.6583E-06 0.03145"/>
      <mass value="0.22652"/>
      <inertia ixx="0.00020005" ixy="-4.2442E-10" ixz="-2.9069E-10" iyy="0.00017832" iyz="-3.4402E-08" izz="0.00013478"/>
    </inertial>
    <visual>
      <origin rpy="0 0 0" xyz="0 0 0"/>
      <geometry>
        <mesh filename="package://scara_e1_description/meshes/scara_bar.stl" scale="0.001 0.001 0.001"/>
      </geometry>
      <material name="Gazebo/White">
        <color rgba="0. 0. 0. 1"/>
      </material>
    </visual>
    <collision>
      <origin rpy="0 0 0" xyz="0 0 0"/>
      <geometry>
        <mesh filename="package://scara_e1_description/meshes/scara_bar.stl" scale="0.001 0.001 0.001"/>
      </geometry>
    </collision>
  </link>
  <link name="scara_e1_fixbar3">
    <inertial>
      <origin rpy="0 0 0" xyz="8.625E-08 -4.6583E-06 0.03145"/>
      <mass value="0.22652"/>
      <inertia ixx="0.00020005" ixy="-4.2442E-10" ixz="-2.9069E-10" iyy="0.00017832" iyz="-3.4402E-08" izz="0.00013478"/>
    </inertial>
    <visual>
      <origin rpy="0 0 0" xyz="0 0 0"/>
      <geometry>
        <mesh filename="package://scara_e1_description/meshes/HEBImotor_fixbar.stl" scale="0.001 0.001 0.001"/>
      </geometry>
      <material name="Gazebo/Grey">
        <color rgba="0. 0. 0. 1"/>
      </material>
    </visual>
    <collision>
      <origin rpy="0 0 0" xyz="0 0 0"/>
      <geometry>
        <mesh filename="package://scara_e1_description/meshes/HEBImotor_fixbar.stl" scale="0.001 0.001 0.001"/>
      </geometry>
    </collision>
  </link>
  <link name="scara_e1_motor4">
    <inertial>
      <origin rpy="0 0 0" xyz="8.625E-08 -4.6583E-06 0.03145"/>
      <mass value="0.22652"/>
      <inertia ixx="0.00020005" ixy="-4.2442E-10" ixz="-2.9069E-10" iyy="0.00017832" iyz="-3.4402E-08" izz="0.00013478"/>
    </inertial>
    <visual>
      <origin rpy="0 0 0" xyz="0 0 0"/>
      <geometry>
        <mesh filename="package://scara_e1_description/meshes/HEBImotor_case.stl" scale="0.001 0.001 0.001"/>
      </geometry>
      <material name="Gazebo/Red">
        <color rgba="0. 0. 0. 1"/>
      </material>
    </visual>
    <collision>
      <origin rpy="0 0 0" xyz="0 0 0"/>
      <geometry>
        <mesh filename="package://scara_e1_description/meshes/HEBImotor_case.stl" scale="0.001 0.001 0.001"/>
      </geometry>
    </collision>
  </link>
  <link name="scara_e1_motor4_inside">
    <inertial>
      <origin rpy="0 0 0" xyz="8.625E-08 -4.6583E-06 0.03145"/>
      <mass value="0.22652"/>
      <inertia ixx="0.00020005" ixy="-4.2442E-10" ixz="-2.9069E-10" iyy="0.00017832" iyz="-3.4402E-08" izz="0.00013478"/>
    </inertial>
    <visual>
      <origin rpy="0 0 0" xyz="0 0 0"/>
      <geometry>
        <mesh filename="package://scara_e1_description/meshes/HEBImotor.stl" scale="0.001 0.001 0.001"/>
      </geometry>
      <material name="Gazebo/Red">
        <color rgba="0. 0. 0. 1"/>
      </material>
    </visual>
    <collision>
      <origin rpy="0 0 0" xyz="0 0 0"/>
      <geometry>
        <mesh filename="package://scara_e1_description/meshes/HEBImotor.stl" scale="0.001 0.001 0.001"/>
      </geometry>
    </collision>
  </link>
  <link name="scara_e1_motor4_support">
    <inertial>
      <origin rpy="0 0 0" xyz="8.625E-08 -4.6583E-06 0.03145"/>
      <mass value="0.22652"/>
      <inertia ixx="0.00020005" ixy="-4.2442E-10" ixz="-2.9069E-10" iyy="0.00017832" iyz="-3.4402E-08" izz="0.00013478"/>
    </inertial>
    <visual>
      <origin rpy="0 0 0" xyz="0 0 0"/>
      <geometry>
        <mesh filename="package://scara_e1_description/meshes/HEBImotor_support.stl" scale="0.001 0.001 0.001"/>
      </geometry>
      <material name="Gazebo/Grey">
        <color rgba="0. 0. 0. 1"/>
      </material>
    </visual>
    <collision>
      <origin rpy="0 0 0" xyz="0 0 0"/>
      <geometry>
        <mesh filename="package://scara_e1_description/meshes/HEBImotor_support.stl" scale="0.001 0.001 0.001"/>
      </geometry>
    </collision>
  </link>
  <link name="scara_e1_bar4">
    <inertial>
      <origin rpy="0 0 0" xyz="8.625E-08 -4.6583E-06 0.03145"/>
      <mass value="0.22652"/>
      <inertia ixx="0.00020005" ixy="-4.2442E-10" ixz="-2.9069E-10" iyy="0.00017832" iyz="-3.4402E-08" izz="0.00013478"/>
    </inertial>
    <visual>
      <origin rpy="0 0 0" xyz="0 0 0"/>
      <geometry>
        <mesh filename="package://scara_e1_description/meshes/scara_bar.stl" scale="0.001 0.001 0.001"/>
      </geometry>
      <material name="Gazebo/White">
        <color rgba="0. 0. 0. 1"/>
      </material>
    </visual>
    <collision>
      <origin rpy="0 0 0" xyz="0 0 0"/>
      <geometry>
        <mesh filename="package://scara_e1_description/meshes/scara_bar.stl" scale="0.001 0.001 0.001"/>
      </geometry>
    </collision>
  </link>
  <link name="scara_e1_rangefinder">
    <inertial>
      <origin rpy="0 0 0" xyz="8.625E-08 -4.6583E-06 0.03145"/>
      <mass value="0.22652"/>
      <inertia ixx="0.00020005" ixy="-4.2442E-10" ixz="-2.9069E-10" iyy="0.00017832" iyz="-3.4402E-08" izz="0.00013478"/>
    </inertial>
    <visual>
      <origin rpy="0 0 0" xyz="0 0 0"/>
      <geometry>
        <mesh filename="package://scara_e1_description/meshes/scara_e1_rangefinder.stl" scale="0.001 0.001 0.001"/>
      </geometry>
      <material name="Gazebo/Blue">
        <color rgba="0. 0. 0. 1"/>
      </material>
    </visual>
    <collision>
      <origin rpy="0 0 0" xyz="0 0 0"/>
      <geometry>
        <mesh filename="package://scara_e1_description/meshes/scara_e1_rangefinder.stl" scale="0.001 0.001 0.001"/>
      </geometry>
    </collision>
  </link>
  <link name="ee_link"/>
  <joint name="world_to_base_joint" type="fixed">
    <origin rpy="0 0 -1.57" xyz="0 0 0"/>
    <parent link="world"/>
    <child link="scara_e1_base_link"/>
  </joint>
  <joint name="logo_joint" type="fixed">
    <origin rpy="0 0 -1.57" xyz="0 -0.332 0.045"/>
    <parent link="world"/>
    <child link="scara_e1_hros_logo"/>
  </joint>
  <joint name="base_to_metraquilato_joint" type="fixed">
    <origin rpy="0 0 -1.57" xyz="0 0 0"/>
    <parent link="world"/>
    <child link="scara_e1_metraquilato"/>
  </joint>
  <joint name="base_to_base_motor_joint" type="fixed">
    <origin rpy="0 0 1.57" xyz="-0.285 0 0.08"/>
    <parent link="scara_e1_base_link"/>
    <child link="scara_e1_base_motor"/>
  </joint>
  <joint name="base_to_motor1_joint" type="fixed">
    <origin rpy="0 0 0" xyz="0 0. 0"/>
    <parent link="scara_e1_base_motor"/>
    <child link="scara_e1_motor1"/>
  </joint>
  <joint name="base_to_motor1_inside_joint" type="fixed">
    <origin rpy="0 0 0" xyz="0 0. 0"/>
    <parent link="scara_e1_motor1"/>
    <child link="scara_e1_motor1_inside"/>
  </joint>
  <joint name="motor1" type="revolute">
    <origin rpy="0 0 1.57" xyz="-0.0313 0 0.0702"/>
    <parent link="scara_e1_motor1_inside"/>
    <child link="scara_e1_motor1_support"/>
    <axis xyz="0 0 1"/>
    <limit effort="10" lower="-3.14" upper="3.14" velocity="10.0"/>
    <dynamics damping="0" friction="0"/>
  </joint>
  <joint name="base_to_bar1_joint" type="fixed">
    <origin rpy="0 0 0" xyz="-0.1155 0. 0.0240"/>
    <parent link="scara_e1_motor1_support"/>
    <child link="scara_e1_bar1"/>
  </joint>
  <joint name="scara_e1_fixbar1_joint" type="fixed">
    <origin rpy="0 0 3.14" xyz="-0.0783 0. 0.0180"/>
    <parent link="scara_e1_bar1"/>
    <child link="scara_e1_fixbar1"/>
  </joint>
  <joint name="base_to_motor2_joint" type="fixed">
    <origin rpy="0 0 3.1416" xyz="0 0. 0"/>
    <parent link="scara_e1_fixbar1"/>
    <child link="scara_e1_motor2"/>
  </joint>
  <joint name="base_to_motor2_inside_joint" type="fixed">
    <origin rpy="0 0 0" xyz="0 0. 0"/>
    <parent link="scara_e1_motor2"/>
    <child link="scara_e1_motor2_inside"/>
  </joint>
  <joint name="motor2" type="revolute">
    <origin rpy="0 0 0" xyz="-0.0313 0 0.0702"/>
    <parent link="scara_e1_motor2_inside"/>
    <child link="scara_e1_motor2_support"/>
    <axis xyz="0 0 1"/>
    <limit effort="10" lower="-3.14" upper="3.14" velocity="10.0"/>
    <dynamics damping="0" friction="0"/>
  </joint>
  <joint name="base_to_bar2_joint" type="fixed">
    <origin rpy="0 0 0" xyz="-0.1155 0. 0.0240"/>
    <parent link="scara_e1_motor2_support"/>
    <child link="scara_e1_bar2"/>
  </joint>
  <joint name="scara_e1_fixbar2_joint" type="fixed">
    <origin rpy="0 0 3.14" xyz="-0.0783 0. 0.0180"/>
    <parent link="scara_e1_bar2"/>
    <child link="scara_e1_fixbar2"/>
  </joint>
  <joint name="base_to_motor3_joint" type="fixed">
    <origin rpy="0 0 3.1416" xyz="0 0. 0"/>
    <parent link="scara_e1_fixbar2"/>
    <child link="scara_e1_motor3"/>
  </joint>
  <joint name="base_to_motor3_inside_joint" type="fixed">
    <origin rpy="0 0 0" xyz="0 0. 0"/>
    <parent link="scara_e1_motor3"/>
    <child link="scara_e1_motor3_inside"/>
  </joint>
  <joint name="motor3" type="revolute">
    <origin rpy="0 0 0" xyz="-0.0313 0 0.0702"/>
    <parent link="scara_e1_motor3_inside"/>
    <child link="scara_e1_motor3_support"/>
    <axis xyz="0 0 1"/>
    <limit effort="10" lower="-3.14" upper="3.14" velocity="10.0"/>
    <dynamics damping="0" friction="0"/>
  </joint>
  <joint name="base_to_bar3_joint" type="fixed">
    <origin rpy="0 0 0" xyz="-0.1155 0. 0.0240"/>
    <parent link="scara_e1_motor3_support"/>
    <child link="scara_e1_bar3"/>
  </joint>
  <joint name="scara_e1_fixbar3_joint" type="fixed">
    <origin rpy="0 0 3.14" xyz="-0.0783 0. 0.0180"/>
    <parent link="scara_e1_bar3"/>
    <child link="scara_e1_fixbar3"/>
  </joint>
  <joint name="base_to_motor4_joint" type="fixed">
    <origin rpy="0 0 3.1416" xyz="0 0. 0"/>
    <parent link="scara_e1_fixbar3"/>
    <child link="scara_e1_motor4"/>
  </joint>
  <joint name="base_to_motor4_inside_joint" type="fixed">
    <origin rpy="0 0 0" xyz="0 0. 0"/>
    <parent link="scara_e1_motor4"/>
    <child link="scara_e1_motor4_inside"/>
  </joint>
  <joint name="motor4" type="revolute">
    <origin rpy="0 0 0" xyz="-0.0313 0 0.0702"/>
    <parent link="scara_e1_motor4_inside"/>
    <child link="scara_e1_motor4_support"/>
    <axis xyz="0 0 1"/>
    <limit effort="10" lower="-3.14" upper="3.14" velocity="10.0"/>
    <dynamics damping="0" friction="0"/>
  </joint>
  <joint name="base_to_bar4_joint" type="fixed">
    <origin rpy="0 0 0" xyz="-0.1155 0. 0.0240"/>
    <parent link="scara_e1_motor4_support"/>
    <child link="scara_e1_bar4"/>
  </joint>
  <joint name="rangefinder_joint" type="fixed">
    <origin rpy="0 0 3.1416" xyz="-0.083 0 0.037"/>
    <parent link="scara_e1_bar4"/>
    <child link="scara_e1_rangefinder"/>
  </joint>
  <joint name="ee_link_joint" type="fixed">
    <origin rpy="0 0 0" xyz="-0.245 0 0"/>
    <parent link="scara_e1_motor4_support"/>
    <child link="ee_link"/>
  </joint>
  <transmission name="motor1_trans">
    <type>transmission_interface/SimpleTransmission</type>
    <joint name="motor1">
      <hardwareInterface>PositionJointInterface</hardwareInterface>
    </joint>
    <actuator name="motor1">
      <mechanicalReduction>1</mechanicalReduction>
    </actuator>
  </transmission>
  <transmission name="moto2_trans">
    <type>transmission_interface/SimpleTransmission</type>
    <joint name="motor2">
      <hardwareInterface>PositionJointInterface</hardwareInterface>
    </joint>
    <actuator name="motor2">
      <mechanicalReduction>1</mechanicalReduction>
    </actuator>
  </transmission>
  <transmission name="motor3_trans">
    <type>transmission_interface/SimpleTransmission</type>
    <joint name="motor3">
      <hardwareInterface>PositionJointInterface</hardwareInterface>
    </joint>
    <actuator name="motor3">
      <mechanicalReduction>1</mechanicalReduction>
    </actuator>
  </transmission>
  <transmission name="motor4_trans">
    <type>transmission_interface/SimpleTransmission</type>
    <joint name="motor4">
      <hardwareInterface>PositionJointInterface</hardwareInterface>
    </joint>
    <actuator name="motor4">
      <mechanicalReduction>1</mechanicalReduction>
    </actuator>
  </transmission>
  <gazebo reference="scara_e1_base_link">
    <material>Gazebo/Grey</material>
    <selfCollide>False</selfCollide>
  </gazebo>
  <gazebo reference="scara_e1_base_motor">
    <material>Gazebo/Grey</material>
    <selfCollide>False</selfCollide>
  </gazebo>
  <gazebo reference="scara_e1_metraquilato">
    <material>Gazebo/Black</material>
    <selfCollide>False</selfCollide>
  </gazebo>
  <gazebo reference="scara_e1_hros_logo">
    <material>Gazebo/Black</material>
    <selfCollide>False</selfCollide>
  </gazebo>
  <gazebo reference="scara_e1_motor1">
    <material>Gazebo/Black</material>
    <selfCollide>False</selfCollide>
  </gazebo>
  <gazebo reference="scara_e1_motor1_inside">
    <material>Gazebo/Red</material>
    <selfCollide>False</selfCollide>
  </gazebo>
  <gazebo reference="scara_e1_motor1_support">
    <material>Gazebo/Grey</material>
    <selfCollide>False</selfCollide>
  </gazebo>
  <gazebo reference="scara_e1_bar1">
    <material>Gazebo/White</material>
    <selfCollide>False</selfCollide>
  </gazebo>
  <gazebo reference="scara_e1_fixbar1">
    <material>Gazebo/White</material>
    <selfCollide>False</selfCollide>
  </gazebo>
  <gazebo reference="scara_e1_motor2">
    <material>Gazebo/Black</material>
    <selfCollide>False</selfCollide>
  </gazebo>
  <gazebo reference="scara_e1_motor2_inside">
    <material>Gazebo/Red</material>
    <selfCollide>False</selfCollide>
  </gazebo>
  <gazebo reference="scara_e1_motor3">
    <material>Gazebo/Black</material>
    <selfCollide>False</selfCollide>
  </gazebo>
  <gazebo reference="scara_e1_motor3_inside">
    <material>Gazebo/Red</material>
    <selfCollide>False</selfCollide>
  </gazebo>
  <gazebo reference="scara_e1_motor3_support">
    <material>Gazebo/Grey</material>
    <selfCollide>False</selfCollide>
  </gazebo>
  <gazebo reference="scara_e1_bar3">
    <material>Gazebo/White</material>
    <selfCollide>False</selfCollide>
  </gazebo>
  <gazebo reference="scara_e1_fixbar3">
    <material>Gazebo/White</material>
    <selfCollide>False</selfCollide>
  </gazebo>
  <gazebo reference="scara_e1_motor4">
    <material>Gazebo/Black</material>
    <selfCollide>False</selfCollide>
  </gazebo>
  <gazebo reference="scara_e1_motor4_inside">
    <material>Gazebo/Red</material>
    <selfCollide>False</selfCollide>
  </gazebo>
  <gazebo reference="scara_e1_bar4">
    <material>Gazebo/White</material>
    <selfCollide>False</selfCollide>
  </gazebo>
  <gazebo reference="scara_e1_rangefinder">
    <material>Gazebo/Blue</material>
    <selfCollide>False</selfCollide>
  </gazebo>
  <gazebo>
    <plugin filename="libgazebo_ros_control.so" name="gazebo_ros_control">
      <robotNamespace>/</robotNamespace>
      <robotSimType>gazebo_ros_control/DefaultRobotHWSim</robotSimType>
    </plugin>
  </gazebo>
  <gazebo reference="ee_link">
    <sensor name="scara_e1_rangefinder_sensor" type="ray">
      <visualize>true</visualize>
      <update_rate>20</update_rate>
      <ray>
        <scan>
          <horizontal>
            <samples>1</samples>
            <resolution>1</resolution>
            <min_angle>-0.17</min_angle>
            <max_angle>0.17</max_angle>
          </horizontal>
          <vertical>
            <samples>40</samples>
            <resolution>1</resolution>
            <min_angle>-1.574</min_angle>
            <max_angle>-1.572</max_angle>
          </vertical>
        </scan>
        <range>
          <min>0</min>
          <max>2</max>
          <resolution>0.01</resolution>
        </range>
      </ray>
      <plugin filename="libgazebo_ros_laser.so" name="laser">
        <topicName>/scan</topicName>
        <frameName>ee_link</frameName>
      </plugin>
    </sensor>
  </gazebo>
</robot>
