<robot
    name="BioloidGP">
  <link
      name="torso">
    <inertial>
      <origin
          xyz="-0.000250324865569353 -0.029407680000666 -0.0227167726210591"
          rpy="0 0 0" />
      <mass
          value="0.323808555028714" />
      <inertia
          ixx="0.000452106276656287"
          ixy="-3.6274580970901E-06"
          ixz="-3.55584170221267E-06"
          iyy="0.000546208431007415"
          iyz="-5.35794321291033E-05"
          izz="0.000433800331086534" />
    </inertial>
    <visual>
      <origin
          xyz="0 0 0"
          rpy="0 0 0" />
      <geometry>
        <mesh
            filename="torsoNoBattery.obj" />
      </geometry>
      <material
          name="">
        <color
            rgba="0.792156862745098 0.819607843137255 0.933333333333333 1" />
      </material>
    </visual>
    <collision>
      <origin
          xyz="0 0 0"
          rpy="0 0 0" />
      <geometry>
        <mesh
            filename="torsoNoBattery.obj" />
      </geometry>
    </collision>
  </link>
  <link
      name="l_hip">
    <inertial>
      <origin
          xyz="-0.0022091131462685 -0.0128045568194227 0.0011465415996348"
          rpy="0 0 0" />
      <mass
          value="0.0496268557535681" />
      <inertia
          ixx="1.48616959606825E-05"
          ixy="6.6137669558419E-08"
          ixz="8.17238964747919E-08"
          iyy="1.09736561394743E-05"
          iyz="2.29192170351274E-07"
          izz="1.5045317979231E-05" />
    </inertial>
    <visual>
      <origin
          xyz="0 0 0"
          rpy="0 0 0" />
      <geometry>
        <mesh
            filename="l_hip.STL" />
      </geometry>
      <material
          name="">
        <color
            rgba="0.792156862745098 0.819607843137255 0.933333333333333 1" />
      </material>
    </visual>
    <collision>
      <origin
          xyz="0 0 0"
          rpy="0 0 0" />
      <geometry>
        <mesh
            filename="l_hip.STL" />
      </geometry>
    </collision>
  </link>
  <joint
      name="l_hip"
      type="revolute">
    <origin
        xyz="0.0159999999999967 0 -0.0765"
        rpy="1.5707963267949 -1.5707963267949 0" />
    <parent
        link="torso" />
    <child
        link="l_hip" />
    <axis
        xyz="0 0 -1" />
    <dynamics damping="0.1" friction="0" />
    <limit effort="200" velocity="12" lower="-2.1000" upper="2.1000" />
    <safety_controller k_position="100" k_velocity="100" soft_lower_limit="-10.6981" soft_upper_limit="10.6981" />
  </joint>
  <link
      name="l_thigh">
    <inertial>
      <origin
          xyz="-0.00100679656416081 -0.0436512889358152 -0.0115146440426869"
          rpy="0 0 0" />
      <mass
          value="0.0943483319483085" />
      <inertia
          ixx="0.000107817177501598"
          ixy="4.03579084705786E-06"
          ixz="-2.58279010663784E-07"
          iyy="2.26809588767613E-05"
          iyz="2.32703245456579E-07"
          izz="0.000108750782236108" />
    </inertial>
    <visual>
      <origin
          xyz="0 0 0"
          rpy="0 0 0" />
      <geometry>
        <mesh
            filename="l_thigh.STL" />
      </geometry>
      <material
          name="">
        <color
            rgba="0.792156862745098 0.819607843137255 0.933333333333333 1" />
      </material>
    </visual>
    <collision>
      <origin
          xyz="0 0 0"
          rpy="0 0 0" />
      <geometry>
        <mesh
            filename="l_thigh.STL" />
      </geometry>
    </collision>
  </link>
  <joint
      name="l_thigh"
      type="revolute">
    <origin
        xyz="-0.0417999999999999 0 0.000399999999996359"
        rpy="-1.57079632679489 -1.0471975511966 -1.38777878078145E-15" />
    <parent
        link="l_hip" />
    <child
        link="l_thigh" />
    <axis
        xyz="0 0 1" />
    <dynamics damping="0.1" friction="0" />
    <limit effort="200" velocity="12" lower="-2.1000" upper="2.1000" />
    <safety_controller k_position="100" k_velocity="100" soft_lower_limit="-10.6981" soft_upper_limit="10.6981" />
  </joint>

  <link
      name="l_shin">
    <inertial>
      <origin
          xyz="-0.0127000000000007 0.0340551332977271 0.015563237763762"
          rpy="0 0 0" />
      <mass
          value="0.00790727972273849" />
      <inertia
          ixx="5.32776553828392E-06"
          ixy="-1.81109996454885E-19"
          ixz="-3.19965088401743E-20"
          iyy="4.22027747361512E-06"
          iyz="3.92003519035654E-07"
          izz="7.78909127423424E-06" />
    </inertial>
    <visual>
      <origin
          xyz="0 0 0"
          rpy="0 0 0" />
      <geometry>
        <mesh
            filename="l_shin.STL" />
      </geometry>
      <material
          name="">
        <color
            rgba="0.792156862745098 0.819607843137255 0.933333333333333 1" />
      </material>
    </visual>
    <collision>
      <origin
          xyz="0 0 0"
          rpy="0 0 0" />
      <geometry>
        <mesh
            filename="l_shin.STL" />
      </geometry>
    </collision>
  </link>
  <joint
      name="l_shin"
      type="revolute">
    <origin
        xyz="-0.0156000000000005 -0.0743999999999996 0"
        rpy="2.0943483319483085 -1.5707963267949 0" />
    <parent
        link="l_thigh" />
    <child
        link="l_shin" />
    <axis
        xyz="1 0 0" />
    <dynamics damping="0.1" friction="0" />
    <limit effort="200" velocity="12" lower="-2.1000" upper="2.1000" />
    <safety_controller k_position="100" k_velocity="100" soft_lower_limit="-10.6981" soft_upper_limit="10.6981" />
  </joint>

  <link
      name="l_heel">
    <inertial>
      <origin
          xyz="-0.0127471904005562 0.019537076734909 0.0118127454835659"
          rpy="0 0 0" />
      <mass
          value="0.0961765714728049" />
      <inertia
          ixx="6.31330083138111E-05"
          ixy="-3.19975987021481E-07"
          ixz="-2.32144687284712E-07"
          iyy="2.59499124215307E-05"
          iyz="5.4845575097287E-07"
          izz="7.1796389444019E-05" />
    </inertial>
    <visual>
      <origin
          xyz="0 0 0"
          rpy="0 0 0" />
      <geometry>
        <mesh
            filename="l_heel.STL" />
      </geometry>
      <material
          name="">
        <color
            rgba="0.792156862745098 0.819607843137255 0.933333333333333 1" />
      </material>
    </visual>
    <collision>
      <origin
          xyz="0 0 0"
          rpy="0 0 0" />
      <geometry>
        <mesh
            filename="l_heel.STL" />
      </geometry>
    </collision>
  </link>
  <joint
      name="l_heel"
      type="revolute">
    <origin
        xyz="0 0.0750000000000011 0.0144999999999982"
        rpy="-1.5707963267949 -0.523598775598291 1.5707963267949" />
    <parent
        link="l_shin" />
    <child
        link="l_heel" />
    <axis
        xyz="0 0 -1" />
    <dynamics damping="0.1" friction="0" />
    <limit effort="200" velocity="12" lower="-2.1000" upper="2.1000" />
    <safety_controller k_position="100" k_velocity="100" soft_lower_limit="-10.6981" soft_upper_limit="10.6981" />
  </joint>

  <link
      name="l_foot">
    <inertial>
      <origin
          xyz="-0.00131235735522086 0.0275947483062579 -0.00415898272684236"
          rpy="0 0 0" />
      <mass
          value="0.017613702318087" />
      <inertia
          ixx="6.4413340155928E-06"
          ixy="-7.4168165680616E-08"
          ixz="3.57223027579177E-08"
          iyy="1.64253742929524E-05"
          iyz="-2.03962455621592E-07"
          izz="1.21662517458466E-05" />
    </inertial>
    <visual>
      <origin
          xyz="0 0 0"
          rpy="0 0 0" />
      <geometry>
        <mesh
            filename="l_foot.STL" />
      </geometry>
      <material
          name="">
        <color
            rgba="0.792156862745098 0.819607843137255 0.933333333333333 1" />
      </material>
    </visual>
    <collision>
      <origin
          xyz="0 0 0"
          rpy="0 0 0" />
      <geometry>
        <mesh
            filename="l_foot_box.obj" />
      </geometry>
    </collision>
  </link>
  <joint
      name="l_foot"
      type="revolute">
    <origin
        xyz="0.000299999999999467 0 0.0121000000000051"
        rpy="-3.14159265358979 3.46944695195361E-16 1.5707963267949" />
    <parent
        link="l_heel" />
    <child
        link="l_foot" />
    <axis
        xyz="1 0 0" />
    <dynamics damping="0.1" friction="0" />
    <limit effort="200" velocity="12" lower="-2.1000" upper="2.1000" />
    <safety_controller k_position="100" k_velocity="100" soft_lower_limit="-10.6981" soft_upper_limit="10.6981" />
  </joint>

  <link
      name="r_hip">
    <inertial>
      <origin
          xyz="0.00220885214673641 -0.0128045568194226 0.00114654159963536"
          rpy="0 0 0" />
      <mass
          value="0.0496268557535681" />
      <inertia
          ixx="1.48616959606825E-05"
          ixy="-6.6303521683512E-08"
          ixz="-8.19551449322855E-08"
          iyy="1.097371336355E-05"
          iyz="2.29192170351272E-07"
          izz="1.50453752033067E-05" />
    </inertial>
    <visual>
      <origin
          xyz="0 0 0"
          rpy="0 0 0" />
      <geometry>
        <mesh
            filename="r_hip.STL" />
      </geometry>
      <material
          name="">
        <color
            rgba="0.792156862745098 0.819607843137255 0.933333333333333 1" />
      </material>
    </visual>
    <collision>
      <origin
          xyz="0 0 0"
          rpy="0 0 0" />
      <geometry>
        <mesh
            filename="r_hip.STL" />
      </geometry>
    </collision>
  </link>
  <joint
      name="r_hip"
      type="revolute">
    <origin
        xyz="-0.0160000000000027 0 -0.0765"
        rpy="1.5707963267949 1.5707963267949 0" />
    <parent
        link="torso" />
    <child
        link="r_hip" />
    <axis
        xyz="0 0 -1" />
    <dynamics damping="0.1" friction="0" />
    <limit effort="200" velocity="12" lower="-2.1000" upper="2.1000" />
    <safety_controller k_position="100" k_velocity="100" soft_lower_limit="-10.6981" soft_upper_limit="10.6981" />
  </joint>

  <link
      name="r_thigh">
    <inertial>
      <origin
          xyz="0.00100665927942036 -0.0436511516510763 -0.0115146440426889"
          rpy="0 0 0" />
      <mass
          value="0.0943483319483086" />
      <inertia
          ixx="0.000107816380949157"
          ixy="-4.03616722263671E-06"
          ixz="2.58048264952533E-07"
          iyy="2.26809849562218E-05"
          iyz="2.32933991165688E-07"
          izz="0.000108750011763128" />
    </inertial>
    <visual>
      <origin
          xyz="0 0 0"
          rpy="0 0 0" />
      <geometry>
        <mesh
            filename="r_thigh.STL" />
      </geometry>
      <material
          name="">
        <color
            rgba="0.792156862745098 0.819607843137255 0.933333333333333 1" />
      </material>
    </visual>
    <collision>
      <origin
          xyz="0 0 0"
          rpy="0 0 0" />
      <geometry>
        <mesh
            filename="r_thigh.STL" />
      </geometry>
    </collision>
  </link>
  <joint
      name="r_thigh"
      type="revolute">
    <origin
        xyz="0.0417999999999985 0 0.000399999999998048"
        rpy="-1.57079632679489 1.0471975511966 1.38777878078145E-15" />
    <parent
        link="r_hip" />
    <child
        link="r_thigh" />
    <axis
        xyz="0 0 -1" />
    <dynamics damping="0.1" friction="0" />
    <limit effort="200" velocity="12" lower="-2.1000" upper="2.1000" />
    <safety_controller k_position="100" k_velocity="100" soft_lower_limit="-10.6981" soft_upper_limit="10.6981" />
  </joint>

  <link
      name="r_shin">
    <inertial>
      <origin
          xyz="0.0126999999999997 0.0340551332977292 0.0155632377637589"
          rpy="0 0 0" />
      <mass
          value="0.00790727972273849" />
      <inertia
          ixx="5.3277655382839E-06"
          ixy="-1.79867730427403E-19"
          ixz="-3.24979242833124E-20"
          iyy="4.22027747361512E-06"
          iyz="3.92003519035653E-07"
          izz="7.78909127423422E-06" />
    </inertial>
    <visual>
      <origin
          xyz="0 0 0"
          rpy="0 0 0" />
      <geometry>
        <mesh
            filename="r_shin.STL" />
      </geometry>
      <material
          name="">
        <color
            rgba="0.792156862745098 0.819607843137255 0.933333333333333 1" />
      </material>
    </visual>
    <collision>
      <origin
          xyz="0 0 0"
          rpy="0 0 0" />
      <geometry>
        <mesh
            filename="r_shin.STL" />
      </geometry>
    </collision>
  </link>
  <joint
      name="r_shin"
      type="revolute">
    <origin
        xyz="0.0156 -0.0743999999999986 0"
        rpy="2.0943951023932 1.5707963267949 0" />
    <parent
        link="r_thigh" />
    <child
        link="r_shin" />
    <axis
        xyz="1 0 0" />
    <dynamics damping="0.1" friction="0" />
    <limit effort="200" velocity="12" lower="-2.1000" upper="2.1000" />
    <safety_controller k_position="100" k_velocity="100" soft_lower_limit="-10.6981" soft_upper_limit="10.6981" />
  </joint>

  <link
      name="r_heel">
    <inertial>
      <origin
          xyz="-0.0127471904005561 0.0195372114099762 -0.0118126108084964"
          rpy="0 0 0" />
      <mass
          value="0.0961765714728048" />
      <inertia
          ixx="6.31324947576051E-05"
          ixy="-3.19810877939643E-07"
          ixz="2.32313682142065E-07"
          iyy="2.59499049784084E-05"
          iyz="-5.48154272615285E-07"
          izz="7.17958833309353E-05" />
    </inertial>
    <visual>
      <origin
          xyz="0 0 0"
          rpy="0 0 0" />
      <geometry>
        <mesh
            filename="r_heel.STL" />
      </geometry>
      <material
          name="">
        <color
            rgba="0.792156862745098 0.819607843137255 0.933333333333333 1" />
      </material>
    </visual>
    <collision>
      <origin
          xyz="0 0 0"
          rpy="0 0 0" />
      <geometry>
        <mesh
            filename="r_heel.STL" />
      </geometry>
    </collision>
  </link>
  <joint
      name="r_heel"
      type="revolute">
    <origin
        xyz="0 0.0750000000000024 0.0144999999999966"
        rpy="-1.5707963267949 -0.523598775598298 1.5707963267949" />
    <parent
        link="r_shin" />
    <child
        link="r_heel" />
    <axis
        xyz="0 0 -1" />
    <dynamics damping="0.1" friction="0" />
    <limit effort="200" velocity="12" lower="-2.1000" upper="2.1000" />
    <safety_controller k_position="100" k_velocity="100" soft_lower_limit="-10.6981" soft_upper_limit="10.6981" />
  </joint>

  <link
      name="r_foot">
    <inertial>
      <origin
          xyz="-0.00131235735521849 0.0275947483062589 0.00415898272684114"
          rpy="0 0 0" />
      <mass
          value="0.017613702318087" />
      <inertia
          ixx="6.44133401559294E-06"
          ixy="-7.41681656806808E-08"
          ixz="-3.5722302757639E-08"
          iyy="1.64253742929524E-05"
          iyz="2.03962455621599E-07"
          izz="1.21662517458467E-05" />
    </inertial>
    <visual>
      <origin
          xyz="0 0 0"
          rpy="0 0 0" />
      <geometry>
        <mesh
            filename="r_foot.STL" />
      </geometry>
      <material
          name="">
        <color
            rgba="0.792156862745098 0.819607843137255 0.933333333333333 1" />
      </material>
    </visual>
    <collision>
      <origin
          xyz="0 0 0"
          rpy="0 0 0" />
      <geometry>
        <mesh
            filename="r_foot_box.obj" />
      </geometry>
    </collision>
  </link>
  <joint
      name="r_foot"
      type="revolute">
    <origin
        xyz="0.0003000000000008 0 -0.0121000000000034"
        rpy="-3.14159265358979 -2.42861286636753E-15 1.5707963267949" />
    <parent
        link="r_heel" />
    <child
        link="r_foot" />
    <axis
        xyz="1 0 0" />
    <dynamics damping="0.1" friction="0" />
    <limit effort="200" velocity="12" lower="-2.1000" upper="2.1000" />
    <safety_controller k_position="100" k_velocity="100" soft_lower_limit="-10.6981" soft_upper_limit="10.6981" />
  </joint>

  <link
      name="l_shoulder">
    <inertial>
      <origin
          xyz="3.99848313369956E-08 -0.00923318844442571 0.00508037063086597"
          rpy="0 0 0" />
      <mass
          value="0.00432191406725111" />
      <inertia
          ixx="8.72162726851168E-07"
          ixy="1.59739093137393E-12"
          ixz="-7.83511401856554E-13"
          iyy="1.89413501942903E-06"
          iyz="-2.56794853568278E-07"
          izz="1.81730737071507E-06" />
    </inertial>
    <visual>
      <origin
          xyz="0 0 0"
          rpy="0 0 0" />
      <geometry>
        <mesh
            filename="l_shoulder.STL" />
      </geometry>
      <material
          name="">
        <color
            rgba="0.792156862745098 0.819607843137255 0.933333333333333 1" />
      </material>
    </visual>
    <collision>
      <origin
          xyz="0 0 0"
          rpy="0 0 0" />
      <geometry>
        <mesh
            filename="l_shoulder.STL" />
      </geometry>
    </collision>
  </link>
  <joint
      name="l_shoulder"
      type="revolute">
    <origin
        xyz="0.056090945471339 -0.00380000000000099 0.000299999999999985"
        rpy="3.14159265358979 -6.12303176911189E-17 -1.5707963267949" />
    <parent
        link="torso" />
    <child
        link="l_shoulder" />
    <axis
        xyz="0 1 0" />
    <dynamics damping="0.1" friction="0" />
    <limit effort="200" velocity="12" lower="-2.1000" upper="2.1000" />
    <safety_controller k_position="100" k_velocity="100" soft_lower_limit="-10.6981" soft_upper_limit="10.6981" />
  </joint>

  <link
      name="l_arm">
    <inertial>
      <origin
          xyz="0.000399125912491638 -0.0352016589942529 0.0031269511037125"
          rpy="0 0 0" />
      <mass
          value="0.0928078955204749" />
      <inertia
          ixx="6.9759461871932E-05"
          ixy="-8.22763944637886E-07"
          ixz="3.02019074715716E-07"
          iyy="2.18725319729742E-05"
          iyz="-3.73674004526739E-06"
          izz="6.39163662787992E-05" />
    </inertial>
    <visual>
      <origin
          xyz="0 0 0"
          rpy="0 0 0" />
      <geometry>
        <mesh
            filename="l_arm.STL" />
      </geometry>
      <material
          name="">
        <color
            rgba="0.792156862745098 0.819607843137255 0.933333333333333 1" />
      </material>
    </visual>
    <collision>
      <origin
          xyz="0 0 0"
          rpy="0 0 0" />
      <geometry>
        <mesh
            filename="l_arm.STL" />
      </geometry>
    </collision>
  </link>
  <joint
      name="l_arm"
      type="revolute">
    <origin
        xyz="0 -0.0230090545286614 0.0180000000000001"
        rpy="-1.5707963267949 5.96311194867027E-17 -1.5707963267949" />
    <parent
        link="l_shoulder" />
    <child
        link="l_arm" />
    <axis
        xyz="0 0 -1" />
    <dynamics damping="0.1" friction="0" />
    <limit effort="200" velocity="12" lower="-2.1000" upper="2.1000" />
    <safety_controller k_position="100" k_velocity="100" soft_lower_limit="-10.6981" soft_upper_limit="10.6981" />
  </joint>

  <link
      name="l_hand">
    <inertial>
      <origin
          xyz="-0.00430436807382556 -0.0484721582738854 0.0164089872229183"
          rpy="0 0 0" />
      <mass
          value="0.0138005964582816" />
      <inertia
          ixx="1.84571140864915E-05"
          ixy="1.00483996060817E-06"
          ixz="-1.03293552796158E-07"
          iyy="4.05560836494352E-06"
          iyz="-1.01861874923564E-06"
          izz="1.84338295416552E-05" />
    </inertial>
    <visual>
      <origin
          xyz="0 0 0"
          rpy="0 0 0" />
      <geometry>
        <mesh
            filename="l_hand.STL" />
      </geometry>
      <material
          name="">
        <color
            rgba="0.792156862745098 0.819607843137255 0.933333333333333 1" />
      </material>
    </visual>
    <collision>
      <origin
          xyz="0 0 0"
          rpy="0 0 0" />
      <geometry>
        <mesh
            filename="l_hand.STL" />
      </geometry>
    </collision>
  </link>
  <joint
      name="l_hand"
      type="revolute">
    <origin
        xyz="0 -0.0574000000000007 0.0178999999999967"
        rpy="-1.5707963267949 0 3.14159265358979" />
    <parent
        link="l_arm" />
    <child
        link="l_hand" />
    <axis
        xyz="1 0 0" />
    <dynamics damping="0.1" friction="0" />
    <limit effort="200" velocity="12" lower="-2.1000" upper="2.1000" />
    <safety_controller k_position="100" k_velocity="100" soft_lower_limit="-10.6981" soft_upper_limit="10.6981" />
  </joint>

  <link
      name="r_shoulder">
    <inertial>
      <origin
          xyz="3.99848294496165E-08 -0.00923318844442551 0.00508037063086597"
          rpy="0 0 0" />
      <mass
          value="0.00432191406725111" />
      <inertia
          ixx="8.72162726851168E-07"
          ixy="1.59739093229708E-12"
          ixz="-7.83511402809347E-13"
          iyy="1.89413501942903E-06"
          iyz="-2.56794853568278E-07"
          izz="1.81730737071507E-06" />
    </inertial>
    <visual>
      <origin
          xyz="0 0 0"
          rpy="0 0 0" />
      <geometry>
        <mesh
            filename="r_shoulder.STL" />
      </geometry>
      <material
          name="">
        <color
            rgba="0.792156862745098 0.819607843137255 0.933333333333333 1" />
      </material>
    </visual>
    <collision>
      <origin
          xyz="0 0 0"
          rpy="0 0 0" />
      <geometry>
        <mesh
            filename="r_shoulder.STL" />
      </geometry>
    </collision>
  </link>
  <joint
      name="r_shoulder"
      type="revolute">
    <origin
        xyz="-0.0560909454713421 -0.00380000000000099 0.00029999999999995"
        rpy="3.14159265358979 6.12303176911189E-17 1.5707963267949" />
    <parent
        link="torso" />
    <child
        link="r_shoulder" />
    <axis
        xyz="0 -1 0" />
    <dynamics damping="0.1" friction="0" />
    <limit effort="200" velocity="12" lower="-2.1000" upper="2.1000" />
    <safety_controller k_position="100" k_velocity="100" soft_lower_limit="-10.6981" soft_upper_limit="10.6981" />
  </joint>

  <link
      name="r_arm">
    <inertial>
      <origin
          xyz="-0.000399265475900426 -0.0352015194308453 0.00312695110371235"
          rpy="0 0 0" />
      <mass
          value="0.0928078955204748" />
      <inertia
          ixx="6.97588868182759E-05"
          ixy="8.22072245539953E-07"
          ixz="-3.0222467174899E-07"
          iyy="2.18725216317411E-05"
          iyz="-3.73654869607888E-06"
          izz="6.391578088391E-05" />
    </inertial>
    <visual>
      <origin
          xyz="0 0 0"
          rpy="0 0 0" />
      <geometry>
        <mesh
            filename="r_arm.STL" />
      </geometry>
      <material
          name="">
        <color
            rgba="0.792156862745098 0.819607843137255 0.933333333333333 1" />
      </material>
    </visual>
    <collision>
      <origin
          xyz="0 0 0"
          rpy="0 0 0" />
      <geometry>
        <mesh
            filename="r_arm.STL" />
      </geometry>
    </collision>
  </link>
  <joint
      name="r_arm"
      type="revolute">
    <origin
        xyz="0 -0.0230090545286614 0.0180000000000001"
        rpy="-1.5707963267949 -5.96311194867027E-17 1.5707963267949" />
    <parent
        link="r_shoulder" />
    <child
        link="r_arm" />
    <axis
        xyz="0 0 -1" />
    <dynamics damping="0.1" friction="0" />
    <limit effort="200" velocity="12" lower="-2.1000" upper="2.1000" />
    <safety_controller k_position="100" k_velocity="100" soft_lower_limit="-10.6981" soft_upper_limit="10.6981" />
  </joint>

  <link
      name="r_hand">
    <inertial>
      <origin
          xyz="0.00430439311781934 0.0484721582738861 -0.0164089872229305"
          rpy="0 0 0" />
      <mass
          value="0.0138005964582816" />
      <inertia
          ixx="1.84571140864922E-05"
          ixy="1.00483116358824E-06"
          ixz="-1.03293913820269E-07"
          iyy="4.05560511306921E-06"
          iyz="-1.01861874924056E-06"
          izz="1.84338262897805E-05" />
    </inertial>
    <visual>
      <origin
          xyz="0 0 0"
          rpy="0 0 0" />
      <geometry>
        <mesh
            filename="r_hand.STL" />
      </geometry>
      <material
          name="">
        <color
            rgba="0.792156862745098 0.819607843137255 0.933333333333333 1" />
      </material>
    </visual>
    <collision>
      <origin
          xyz="0 0 0"
          rpy="0 0 0" />
      <geometry>
        <mesh
            filename="r_hand.STL" />
      </geometry>
    </collision>
  </link>
  <joint
      name="r_hand"
      type="revolute">
    <origin
        xyz="0 -0.0574000000000003 0.0178999999999966"
        rpy="1.5707963267949 0 3.14159265358979" />
    <parent
        link="r_arm" />
    <child
        link="r_hand" />
    <axis
        xyz="1 0 0" />
    <dynamics damping="0.1" friction="0" />
    <limit effort="200" velocity="12" lower="-2.1000" upper="2.1000" />
    <safety_controller k_position="100" k_velocity="100" soft_lower_limit="-10.6981" soft_upper_limit="10.6981" />
  </joint>

</robot>
