<?xml version="1.0" ?>
<!-- =================================================================================== -->
<!-- |    This document was autogenerated by xacro from scara_e1_model_3joints.urdf.xacro | -->
<!-- |    EDITING THIS FILE BY HAND IS NOT RECOMMENDED                                 | -->
<!-- =================================================================================== -->
<robot name="hans_arm_3joints" xmlns:xacro="http://ros.org/wiki/xacro">
  <link name="world">
    <visual>
      <geometry>
        <box size="1.5 0.8 0.001"/>
      </geometry>
      <origin rpy="0 0 0" xyz="0 0 0"/>
      <material name="Gazebo/Black">
       </material>
    </visual>
  </link>

  <link name="hans_arm_base_link">
    <inertial>
      <origin rpy="0 0 0" xyz="8.625E-08 -4.6583E-06 0.03145"/>
      <mass value="7.033"/>
      <inertia ixx="0.1478344" ixy="-0.00001" ixz="0.0" iyy="0.14782335" iyz="0.0" izz="0.29471799"/>
    </inertial>
    <visual>
      <origin rpy="0 0 0" xyz="0 0 0"/>
      <geometry>
        <mesh filename="package://hans_arm_description/meshes/H-ROS_Robot_BASE.stl" scale="0.001 0.001 0.001"/>
      </geometry>
      <material name="Gazebo/Grey">
        <color rgba="0. 0. 0. 1"/>
      </material>
    </visual>
    <collision>
      <origin rpy="0 0 0" xyz="0 0 0"/>
      <geometry>
        <mesh filename="package://hans_arm_description/meshes/H-ROS_Robot_BASE.stl" scale="0.001 0.001 0.001"/>
      </geometry>
    </collision>
  </link>
  <gazebo reference="hans_arm_base_link">
    <material>Gazebo/Grey</material>
    <selfCollide>False</selfCollide>
  </gazebo>

  <link name="motor1_link">
    <inertial>
      <origin rpy="0 0 0" xyz="8.625E-08 -4.6583E-06 0.03145"/>
      <mass value="5.8"/>
      <inertia ixx="0.10105893" ixy="0.000211" ixz="-0.004" iyy="0.09386624" iyz="-0.01698537" izz="0.01449937"/>
    </inertial>
    <visual>
      <origin rpy="0 0 0" xyz="0 0 0"/>
      <geometry>
        <mesh filename="package://hans_arm_description/meshes/H-ROS_Robot_HANS1.stl" scale="0.001 0.001 0.001"/>
      </geometry>
      <material name="Gazebo/Grey">
        <color rgba="0. 0. 0. 1"/>
      </material>
    </visual>
    <collision>
      <origin rpy="0 0 0" xyz="0 0 0"/>
      <geometry>
        <mesh filename="package://hans_arm_description/meshes/H-ROS_Robot_HANS1.stl" scale="0.001 0.001 0.001"/>
      </geometry>
    </collision>
  </link>
  <gazebo reference="motor1_link">
    <material>Gazebo/Grey</material>
    <selfCollide>False</selfCollide>
  </gazebo>

  <link name="link1">
    <inertial>
      <origin rpy="0 0 0" xyz="8.625E-08 -4.6583E-06 0.03145"/>
      <mass value="1.03237"/>
      <inertia ixx="0.014865226" ixy="0.0" ixz="0.0" iyy="0.01557" iyz="0.00071" izz="0.00092"/>
    </inertial>
    <visual>
      <origin rpy="0 0 0" xyz="0 0 0"/>
      <geometry>
        <mesh filename="package://hans_arm_description/meshes/H-ROS_Robot_LINK1.stl" scale="0.001 0.001 0.001"/>
      </geometry>
      <material name="Gazebo/Grey">
        <color rgba="0. 0. 0. 1"/>
      </material>
    </visual>
    <collision>
      <origin rpy="0 0 0" xyz="0 0 0"/>
      <geometry>
        <mesh filename="package://hans_arm_description/meshes/H-ROS_Robot_LINK1.stl" scale="0.001 0.001 0.001"/>
      </geometry>
    </collision>
  </link>
  <gazebo reference="link1">
    <material>Gazebo/Grey</material>
    <selfCollide>False</selfCollide>
  </gazebo>

  <link name="motor3_link">
    <inertial>
      <origin rpy="0 0 0" xyz="8.625E-08 -4.6583E-06 0.03145"/>
      <mass value="3.8"/>
      <inertia ixx="0.04517" ixy="0.00002" ixz="0.0" iyy="0.01587" iyz="0.01444" izz="0.03303"/>
    </inertial>
    <visual>
      <origin rpy="0 0 0" xyz="0 0 0"/>
      <geometry>
        <mesh filename="package://hans_arm_description/meshes/H-ROS_Robot_HANS2.stl" scale="0.001 0.001 0.001"/>
      </geometry>
      <material name="Gazebo/Grey">
        <color rgba="0. 0. 0. 1"/>
      </material>
    </visual>
    <collision>
      <origin rpy="0 0 0" xyz="0 0 0"/>
      <geometry>
        <mesh filename="package://hans_arm_description/meshes/H-ROS_Robot_HANS2.stl" scale="0.001 0.001 0.001"/>
      </geometry>
    </collision>
  </link>
  <gazebo reference="motor3_link">
    <material>Gazebo/Grey</material>
    <selfCollide>False</selfCollide>
  </gazebo>

  <link name="motor4_link">
    <inertial>
      <origin rpy="0 0 0" xyz="8.625E-08 -4.6583E-06 0.03145"/>
      <mass value="1.1"/>
      <inertia ixx="0.01464" ixy="0.0" ixz="0.0" iyy="0.00895" iyz="-0.00631" izz="0.00725"/>
    </inertial>
    <visual>
      <origin rpy="0 0 0" xyz="0 0 0"/>
      <geometry>
        <mesh filename="package://hans_arm_description/meshes/H-ROS_Robot_LINK2.stl" scale="0.001 0.001 0.001"/>
      </geometry>
      <material name="Gazebo/Grey">
        <color rgba="0. 0. 0. 1"/>
      </material>
    </visual>
    <collision>
      <origin rpy="0 0 0" xyz="0 0 0"/>
      <geometry>
        <mesh filename="package://hans_arm_description/meshes/H-ROS_Robot_LINK2.stl" scale="0.001 0.001 0.001"/>
      </geometry>
    </collision>
  </link>
  <gazebo reference="motor4_link">
    <material>Gazebo/Grey</material>
    <selfCollide>False</selfCollide>
  </gazebo>

  <link name="motor5_link">
    <inertial>
      <origin rpy="0 0 0" xyz="8.625E-08 -4.6583E-06 0.03145"/>
      <mass value="2.9"/>
      <inertia ixx="0.03406" ixy="0.0" ixz="0.0" iyy="0.01066" iyz="0.00989" izz="0.02563"/>
    </inertial>
    <visual>
      <origin rpy="0 0 0" xyz="0 0 0"/>
      <geometry>
        <mesh filename="package://hans_arm_description/meshes/H-ROS_Robot_HANS3.stl" scale="0.001 0.001 0.001"/>
      </geometry>
      <material name="Gazebo/Grey">
        <color rgba="0. 0. 0. 1"/>
      </material>
    </visual>
    <collision>
      <origin rpy="0 0 0" xyz="0 0 0"/>
      <geometry>
        <mesh filename="package://hans_arm_description/meshes/H-ROS_Robot_HANS3.stl" scale="0.001 0.001 0.001"/>
      </geometry>
    </collision>
  </link>
  <gazebo reference="motor5_link">
    <material>Gazebo/Grey</material>
    <selfCollide>False</selfCollide>
  </gazebo>

  <joint name="world_to_base_joint" type="fixed">
    <origin rpy="0 0 0" xyz="0 0 0.02"/>
    <parent link="world"/>
    <child link="hans_arm_base_link"/>
  </joint>

  <joint name="motor1" type="revolute">
    <origin rpy="0 0 0" xyz="0 0 0.00625"/>
    <parent link="hans_arm_base_link"/>
    <child link="motor1_link"/>
    <axis xyz="0 0 1"/>
    <limit effort="10" lower="-3.1416" upper="3.1416" velocity="10.0"/>
    <dynamics damping="0" friction="0"/>
  </joint>

  <joint name="motor2" type="revolute">
    <origin rpy="0 0 0" xyz="0 -0.100499999 0.1545"/>
    <parent link="motor1_link"/>
    <child link="link1"/>
    <axis xyz="0 1 0"/>
    <limit effort="10" lower="-3.1416" upper="3.1416" velocity="10.0"/>
    <dynamics damping="0" friction="0"/>
  </joint>

  <joint name="motor3" type="revolute">
    <origin rpy="0 0 0" xyz="0 -0.000499999 0.2"/>
    <parent link="link1"/>
    <child link="motor3_link"/>
    <axis xyz="0 1 0"/>
    <limit effort="10" lower="-3.1416" upper="3.1416" velocity="10.0"/>
    <dynamics damping="0" friction="0"/>
  </joint>

  <joint name="motor4" type="revolute">
    <origin rpy="0 0 0" xyz="0 0.09999 0.12999997"/>
    <parent link="motor3_link"/>
    <child link="motor4_link"/>
    <axis xyz="0 0 1"/>
    <limit effort="10" lower="-3.1416" upper="3.1416" velocity="10.0"/>
    <dynamics damping="0" friction="0"/>
  </joint>

  <joint name="motor5" type="revolute">
    <origin rpy="0 0 0" xyz="0 -0.096999 0.15906"/>
    <parent link="motor4_link"/>
    <child link="motor5_link"/>
    <axis xyz="0 1 0"/>
    <limit effort="10" lower="-3.1416" upper="3.1416" velocity="10.0"/>
    <dynamics damping="0" friction="0"/>
  </joint>

  <transmission name="motor1_trans">
    <type>transmission_interface/SimpleTransmission</type>
    <joint name="motor1">
      <hardwareInterface>hardware_interface/PositionJointInterface</hardwareInterface>
    </joint>
    <actuator name="motor1">
      <mechanicalReduction>1</mechanicalReduction>
    </actuator>
  </transmission>
  <transmission name="motor2_trans">
    <type>transmission_interface/SimpleTransmission</type>
    <joint name="motor2">
      <hardwareInterface>hardware_interface/PositionJointInterface</hardwareInterface>
    </joint>
    <actuator name="motor2">
      <mechanicalReduction>1</mechanicalReduction>
    </actuator>
  </transmission>
  <transmission name="motor3_trans">
    <type>transmission_interface/SimpleTransmission</type>
    <joint name="motor3">
      <hardwareInterface>hardware_interface/PositionJointInterface</hardwareInterface>
    </joint>
    <actuator name="motor3">
      <mechanicalReduction>1</mechanicalReduction>
    </actuator>
  </transmission>
  <transmission name="motor4_trans">
    <type>transmission_interface/SimpleTransmission</type>
    <joint name="motor4">
      <hardwareInterface>hardware_interface/PositionJointInterface</hardwareInterface>
    </joint>
    <actuator name="motor4">
      <mechanicalReduction>1</mechanicalReduction>
    </actuator>
  </transmission>
  <transmission name="motor5_trans">
    <type>transmission_interface/SimpleTransmission</type>
    <joint name="motor5">
      <hardwareInterface>hardware_interface/PositionJointInterface</hardwareInterface>
    </joint>
    <actuator name="motor5">
      <mechanicalReduction>1</mechanicalReduction>
    </actuator>
  </transmission>

  <gazebo>
    <plugin filename="libgazebo_ros_control.so" name="gazebo_ros_control">
      <robotNamespace>/</robotNamespace>
      <robotSimType>gazebo_ros_control/DefaultRobotHWSim</robotSimType>
    </plugin>
  </gazebo>

</robot>
