<mujoco model="reacher">
	<compiler angle="radian" inertiafromgeom="true"/>
	<default>
		<joint armature="0" damping="2" limited="true"/>
		<geom contype="0" friction="1 0.1 0.1" rgba="0.7 0.7 0 1"/>
	</default>
	<option gravity="0 0 0" integrator="RK4" timestep="0.002"/>
	<worldbody>
		<!-- Arm -->
		<body name="body0" pos="0 0 0">
			<geom contype="0" pos="0 0 0" mass="1" name="link0" rgba="0.0 0.4 0.6 1" size="0.05 0.25 0.05" type="box"/>
			<joint axis="0 0 1" limited="true" range="-3.14 3.14" name="joint0_f" pos="0 0.25 0" type="hinge"/>
			<joint axis="1 0 0" limited="true" range="-3.14 3.14" name="joint0_h" pos="0 0.25 0" type="hinge"/>
			<body name="body1" pos="0 -0.5 0">
				<joint axis="0 0 1" limited="true" range="-3.14 3.14" name="joint1" pos="0 0.25 0" type="hinge"/>
				<geom contype="0" pos="0 0 0" mass="1" name="link1" rgba="0.0 0.4 0.6 1" size="0.05 0.25 0.05" type="box"/>
                <body name="body2" pos="0 -0.5 0">
                    <geom contype="0" pos="0 0 0" mass="1" name="link2" rgba="0.0 0.4 0.6 1" size="0.05 0.25 0.05" type="box"/>
			        <joint axis="0 0 1" limited="true" range="-3.14 3.14" name="joint2_f" pos="0 0.25 0" type="hinge"/>
			        <joint axis="1 0 0" limited="true" range="-3.14 3.14" name="joint2_h" pos="0 0.25 0" type="hinge"/>
				    <body name="fingertip" pos="0 -0.25 0">
					    <geom contype="0" name="fingertip" pos="0 0 0" mass="0" rgba="0.0 0.8 0.6 1" size=".1" type="sphere"/>
                    </body>
				</body>
			</body>
		</body>
		<!-- Target -->
		<body name="target" pos="0 0 0">
			<joint armature="0" axis="1 0 0" damping="0" limited="false" name="target_x" pos="0 0 0" stiffness="0" type="slide"/>
			<joint armature="0" axis="0 1 0" damping="0" limited="false" name="target_y" pos="0 0 0" stiffness="0" type="slide"/>
            <joint armature="0" axis="0 0 1" damping="0" limited="false" name="target_z" pos="0 0 0" stiffness="0" type="slide"/>
			<geom conaffinity="0" contype="0" name="target" pos="0 0 0" rgba="0.9 0.2 0.2 1" size=".09" type="sphere"/>
		</body>
	</worldbody>
	<actuator>
		<motor ctrllimited="true" ctrlrange="-1.0 1.0" gear="10.0" joint="joint0_f"/>
		<motor ctrllimited="true" ctrlrange="-1.0 1.0" gear="10.0" joint="joint0_h"/>
        <motor ctrllimited="true" ctrlrange="-1.0 1.0" gear="10.0" joint="joint1"/>
		<motor ctrllimited="true" ctrlrange="-1.0 1.0" gear="10.0" joint="joint2_f"/>
        <motor ctrllimited="true" ctrlrange="-1.0 1.0" gear="10.0" joint="joint2_h"/>
	</actuator>
</mujoco>